Workbook

Sheet 会员总表
A1: 序号 | B1: 加入时间 | C1: 会籍时间 | D1: 姓名 | E1: 性别 | F1: 面试官 | G1: 推荐人 | H1: 推荐人分会 | I1: 推荐大类 | J1: 是否更新 | K1: 地区 | L1: 所在位置 | M1: 公司 | N1: 职位 | O1: 会员类型 | P1: 会员编号 | Q1: 是否入组 | R1: 新会员接待 | S1: 新会员培训时间 | T1: 培训师 | U1: 上线官网 | V1: 新学员见面直播 | W1: 是否续费 | X1: 备注 | Y1: 出海 | Z1: 加入时长 | AA1: 过期 | AB1: 续费金额 | AC1: 推荐人 | AD1: 推荐大类 | AE1: 邮箱 | AF1: 备注 | AG1: 饭团 | AH1: 分会活动 | AI1: 累计 | AJ1: 活跃度打分
A2: 1 | B2: 42129 | C2: 46203 | D2: 艾芙（徐雁斐） | E2: 女 | G2: 暂无 | I2: 暂无 | J2: 1 | K2: 深圳 | M2: 暂无 | N2: 暂无 | O2: 标准会员 | P2: 1 | S2: - | T2: - | U2: 1 | AE2: elfe1021@gmail.com
A3: 2 | B3: 42132 | C3: 46203 | D3: 郭理靖 | E3: 男 | G3: 暂无 | I3: 暂无 | J3: 1 | K3: 杭州 | M3: 奈雪的茶 | N3: CTO | O3: 标准会员 | P3: 2 | S3: - | T3: - | U3: 1 | X3: 1 | Y3: 1 | AE3: guolijing@gmail.com
A4: 3 | B4: 42139 | C4: 46203 | D4: 陈锡言 | E4: 男 | G4: 暂无 | I4: 暂无 | J4: 无信息0 | K4: 北京 | M4: 一览科技 | N4: 联合创始人 | O4: 标准会员 | P4: 5 | Q4: 北京0组 | R4: 0 | S4: - | T4: - | U4: 1 | Y4: 1 | AB4: 已续费 | AE4: cccsmoking@sina.com | AG4: 1 | AH4: 2 | AI4: 3 | AJ4: B
A5: 4 | B5: 42146 | C5: 46203 | D5: 汪威 | E5: 男 | G5: 暂无 | I5: 暂无 | J5: 1 | K5: 北京 | M5: 心语未来 | N5: CEO | O5: 高级会员 | P5: 12 | Q5: 北京0组 | R5: 0 | S5: - | T5: - | U5: 1 | Y5: 1 | AB5: 已续费 | AE5: wangcash@gmail.com | AG5: 0 | AH5: 0 | AI5: 0 | AJ5: D
A6: 5 | B6: 42147 | C6: 46203 | D6: 唐小浙 | E6: 男 | G6: 暂无 | I6: 暂无 | J6: 1 | K6: 上海 | M6: 墨誉科技 | N6: 技术vp | O6: 标准会员 | P6: 13 | S6: - | T6: - | U6: 1 | Y6: 1 | AE6: tangxz@gmail.com
A7: 6 | B7: 42150 | C7: 46203 | D7: 邹光先 | E7: 男 | G7: 暂无 | I7: 暂无 | J7: 0 | K7: 广州 | M7: 其他 | N7: 其他 | O7: 标准会员 | P7: 14 | S7: - | T7: - | U7: 1 | Y7: 1 | AE7: zouguangxian@163.com
A8: 7 | B8: 42160 | C8: 46203 | D8: 黄良懿 | E8: 男 | G8: 暂无 | I8: 暂无 | J8: 1 | K8: 深圳 | M8: 高仙机器人 | N8: 研发VP | O8: 标准会员 | P8: 17 | S8: - | T8: - | U8: 1 | Y8: 1 | AE8: codeant@hotmail.com
A9: 8 | B9: 42171 | C9: 46203 | D9: 史海峰 | E9: 男 | G9: 暂无 | I9: 暂无 | J9: 1 | K9: 北京 | M9: 方正证券 | N9: 架构平台负责人 | O9: 标准会员 | P9: 23 | Q9: 北京2组 | R9: 0 | S9: - | T9: - | U9: 1 | X9: 1 | Y9: 1 | AB9: 已续费 | AE9: shihf_dc@163.com | AG9: 17 | AH9: 9 | AI9: 26 | AJ9: A
A10: 9 | B10: 42180 | C10: 46203 | D10: 梁宇鹏 | E10: 男 | G10: 暂无 | I10: 暂无 | J10: 0 | K10: 北京 | M10: 蓝莺IM | N10: CEO | O10: 标准会员 | P10: 24 | Q10: 北京2组 | R10: 0 | S10: - | T10: - | U10: 1 | Y10: 1 | AB10: 已续费 | AE10: eric.l.2046@gmail.com | AG10: 11 | AH10: 5 | AI10: 16 | AJ10: A
A11: 10 | B11: 42202 | C11: 46203 | D11: 熊昌伟 | E11: 男 | G11: 暂无 | I11: 暂无 | J11: 1 | K11: 北京 | M11: 畅捷通信息技术有限公司 | N11: 助理总裁 | O11: 标准会员 | P11: 29 | Q11: 北京0组 | R11: 0 | S11: - | T11: - | U11: 1 | Y11: 1 | AB11: 已续费 | AE11: xcw@chanjet.com | AG11: 1 | AH11: 3 | AI11: 4 | AJ11: B
A12: 11 | B12: 42209 | C12: 46203 | D12: 丁宁 | E12: 男 | G12: 暂无 | I12: 暂无 | J12: 无公司 | K12: 新加坡 | M12: 荔枝集团 | N12: CTO | O12: 高级会员 | P12: 30 | S12: - | T12: - | U12: 1 | X12: 1 | Y12: 1 | AE12: dingning@lizhi.fm
A13: 12 | B13: 42219 | C13: 46203 | D13: 陈靖华 | E13: 男 | G13: 暂无 | I13: 暂无 | J13: 1 | K13: 北京 | M13: 北京基调网络股份有限公司 | N13: CEO | O13: 标准会员 | P13: 34 | Q13: 北京2组 | R13: 0 | S13: - | T13: - | U13: 1 | Y13: 1 | AB13: 已续费 | AE13: wood@tingyun.com | AG13: 0 | AH13: 1 | AI13: 1 | AJ13: C
A14: 13 | B14: 42221 | C14: 46203 | D14: 侯冬雯 | E14: 女 | G14: 暂无 | I14: 暂无 | J14: 无公司 | K14: 北京 | M14: 北京微梦传媒 | N14: CTO | O14: 高级会员 | P14: 38 | Q14: 北京0组 | R14: 0 | S14: - | T14: - | U14: 1 | Y14: 1 | AB14: 已续费 | AE14: dongwen@microdreams.com.cn | AG14: 0 | AH14: 0 | AI14: 0 | AJ14: D
A15: 14 | B15: 42246 | C15: 46203 | D15: 黄彬彬 | E15: 男 | G15: 暂无 | I15: 暂无 | J15: 1 | K15: 上海 | M15: 多云转晴 | N15: 架构师 | O15: 高级会员 | P15: 44 | S15: - | T15: - | U15: 1 | Y15: 1 | AE15: 118733@qq.com
A16: 15 | B16: 42248 | C16: 46203 | D16: 王立博 | E16: 男 | G16: 暂无 | I16: 暂无 | J16: 1 | K16: 上海 | M16: 未来保贝 | N16: 合伙人&CTO | O16: 标准会员 | P16: 48 | S16: - | T16: - | U16: 1 | Y16: 1 | AE16: w803007@163.com
A17: 16 | B17: 42256 | C17: 46203 | D17: 胡震 | E17: 男 | G17: 暂无 | I17: 暂无 | J17: 1 | K17: 上海 | M17: 某公链基金会 | N17: 投研负责人 | O17: 标准会员 | P17: 58 | S17: - | T17: - | U17: 1 | Y17: 1 | AE17: huzhencn@163.com
A18: 17 | B18: 42275 | C18: 46203 | D18: 洪强宁 | E18: 男 | G18: 暂无 | I18: 暂无 | J18: 1 | K18: 北京 | M18: 雅识科技 | N18: 联合创始人兼CTO | O18: 标准会员 | P18: 65 | Q18: 北京2组 | R18: 0 | S18: - | T18: - | U18: 1 | Y18: 1 | AB18: 已续费 | AE18: hongqn@gmail.com | AG18: 0 | AH18: 0 | AI18: 0 | AJ18: C
A19: 18 | B19: 42298 | C19: 46203 | D19: 李道兵 | E19: 男 | G19: 暂无 | I19: 暂无 | J19: 1 | K19: 北京 | M19: Fortinet Principal Embedded Software Developer | N19: 创始人 | O19: 标准会员 | P19: 70 | Q19: 北京0组 | R19: 0 | S19: - | T19: - | U19: 1 | Y19: 1 | AB19: 无需续费 | AE19: lidaobing@gmail.com | AG19: 0 | AH19: 0 | AI19: 0 | AJ19: D
A20: 19 | B20: 42300 | C20: 46203 | D20: 张海龙 | E20: 男 | G20: 暂无 | I20: 暂无 | J20: 1 | K20: 苏州 | M20: 同程旅行 | N20: 技术委员会主任 | O20: 标准会员 | P20: 72 | S20: - | T20: - | U20: 1 | X20: 1 | Y20: 1 | AE20: zhanghailong@coding.net
A21: 20 | B21: 42300 | C21: 46203 | D21: 王晓波 | E21: 男 | G21: 暂无 | I21: 暂无 | J21: 0 | K21: 苏州 | M21: 同程旅行 | N21: AVP&出行事业群 CTO | O21: 标准会员 | P21: 71 | S21: - | T21: - | U21: 1 | Y21: 1 | AE21: wxb09195@ly.com
A22: 21 | B22: 42318 | C22: 46203 | D22: 林华根 | E22: 男 | G22: 暂无 | I22: 暂无 | J22: 1 | K22: 深圳 | M22: 安徽超远信息技术有限公司 | N22: 副总工程师 | O22: 标准会员 | P22: 78 | S22: - | T22: - | U22: 1 | Y22: 1 | AE22: lhg@cychina.cn
A23: 22 | B23: 42334 | C23: 46203 | D23: 魏吉贺 | E23: 男 | G23: 暂无 | I23: 暂无 | J23: 1 | K23: 深圳 | M23: 深圳市残友软件股份有限公司 | N23: 技术总监 | O23: 标准会员 | P23: 91 | S23: - | T23: - | U23: 1 | Y23: 1 | AE23: wjh@canyou.cn
A24: 23 | B24: 42339 | C24: 46203 | D24: 龚银 | E24: 男 | G24: 暂无 | I24: 暂无 | J24: 1 | K24: 深圳 | M24: 安克创新 | N24: CIO | O24: 标准会员 | P24: 95 | S24: - | T24: - | U24: 1 | Y24: 1 | AE24: gongyin@126.com
A25: 24 | B25: 42361 | C25: 46203 | D25: 华健 | E25: 男 | G25: 暂无 | I25: 暂无 | J25: 1 | K25: 北京 | M25: 北京梦诚科技 | N25: CTO | O25: 标准会员 | P25: 102 | Q25: 北京2组 | R25: 0 | S25: - | T25: - | U25: 1 | Y25: 1 | AB25: 已续费 | AE25: huaj1101@qq.com | AG25: 0 | AH25: 2 | AI25: 2 | AJ25: C
A26: 25 | B26: 42427 | C26: 46203 | D26: 何世友 | E26: 男 | G26: 暂无 | I26: 暂无 | J26: 1 | K26: 广州 | M26: 腾讯云 | N26: Serverless 产品负责人 | O26: 标准会员 | P26: 114 | S26: - | T26: - | U26: 1 | Y26: 1 | AE26: shiyou.he@gmail.com
A27: 26 | B27: 42433 | C27: 46203 | D27: 李玉福 | E27: 男 | G27: 暂无 | I27: 暂无 | J27: 1 | K27: 北京 | M27: 农信互联 | N27: 副总裁 | O27: 标准会员 | P27: 117 | Q27: 北京15组 | R27: 0 | S27: - | T27: - | U27: 1 | Y27: 1 | AB27: 已续费 | AE27: liyufu@nxin.com | AG27: 2 | AH27: 2 | AI27: 4 | AJ27: B
A28: 27 | B28: 42451 | C28: 46203 | D28: 曾冠东 | E28: 男 | G28: 暂无 | I28: 暂无 | J28: 0 | K28: 广州 | M28: 酷狗音乐 | N28: 繁星网研发总监 | O28: 标准会员 | P28: 123 | S28: - | T28: - | U28: 1 | X28: 1 | Y28: 1 | AE28: popeast@gmail.com
A29: 28 | B29: 42451 | C29: 46203 | D29: 路文杰 | E29: 男 | G29: 暂无 | I29: 暂无 | J29: 1 | K29: 广州 | M29: 甘果科技 | N29: CEO | O29: 标准会员 | P29: 121 | S29: - | T29: - | U29: 1 | AE29: cngump@gmail.com
A30: 29 | B30: 42473 | C30: 46203 | D30: 高楚涛 | E30: 男 | G30: 暂无 | I30: 暂无 | J30: 1 | K30: 深圳 | M30: 深圳市嘉立创科技发展有限公司 | N30: CIO | O30: 标准会员 | P30: 135 | S30: - | T30: - | U30: 1 | Y30: 1 | AE30: gaochutao@163.com
A31: 30 | B31: 42480 | C31: 46203 | D31: 刘建国 | E31: 男 | G31: 暂无 | I31: 暂无 | J31: 1 | K31: 广州 | L31: 1 | M31: 伊智信息科技 | N31: CEO | O31: 标准会员 | P31: 26 | S31: - | T31: - | U31: 1 | Y31: 1 | AE31: yijshu@gmail.com
A32: 31 | B32: 42482 | C32: 46203 | D32: 万林涛 | E32: 男 | G32: 暂无 | I32: 暂无 | J32: 1 | K32: 上海 | M32: 上海蔚星数据 | N32: 副总裁兼首席数据官 | O32: 标准会员 | P32: 140 | S32: - | T32: - | U32: 1 | Y32: 1 | AE32: lintao.wan@outlook.com
A33: 32 | B33: 42482 | C33: 46203 | D33: 徐翎 | E33: 男 | G33: 暂无 | I33: 暂无 | J33: 1 | K33: 上海 | M33: 上海数达物流科技有限公司 | N33: CTO | O33: 标准会员 | P33: 139 | S33: - | T33: - | U33: 1 | AE33: xlshcn@hotmail.com
A34: 33 | B34: 42495 | C34: 46203 | D34: 肖颖 | E34: 男 | G34: 暂无 | I34: 暂无 | J34: １ | K34: 上海 | M34: 上海澄廓信息科技有限公司 | N34: CEO | O34: 标准会员 | P34: 144 | S34: - | T34: - | U34: 1 | AE34: 18049722632@163.com
A35: 34 | B35: 42524 | C35: 46203 | D35: 张剑伟 | E35: 男 | G35: 暂无 | I35: 暂无 | J35: １ | K35: 上海 | M35: 百安居 | N35: CTO | O35: 标准会员 | P35: 160 | S35: - | T35: - | U35: 1 | AE35: zjwsoft@gmail.com
A36: 35 | B36: 42536 | C36: 46203 | D36: 苏煦烽 | E36: 男 | G36: 暂无 | I36: 暂无 | J36: １ | K36: 广州 | L36: 1 | M36: 亲邻科技 | N36: 技术总监 | O36: 标准会员 | P36: 167 | S36: - | T36: - | U36: 1 | Y36: 1 | AE36: suxufeng@qq.com
A37: 36 | B37: 42537 | C37: 46203 | D37: 孙其瑞 | E37: 男 | G37: 暂无 | I37: 暂无 | J37: １ | K37: 杭州 | M37: 苏州优频科技有限公司 | N37: CTO | O37: 标准会员 | P37: 171 | S37: - | T37: - | U37: 1 | Y37: 1 | AE37: sqr@detu.com
A38: 37 | B38: 42552 | C38: 46203 | D38: 芦宇峰 | E38: 男 | G38: 暂无 | I38: 暂无 | J38: １ | K38: 杭州 | M38: 上海擎路科技 | N38: 联合创始人 & CTO | O38: 标准会员 | P38: 178 | S38: - | T38: - | U38: 1 | Y38: 1 | AE38: xiao_ys@163.com
A39: 38 | B39: 42556 | C39: 46203 | D39: 陈杰 | E39: 男 | G39: 暂无 | I39: 暂无 | J39: １ | K39: 上海 | M39: 上海领健信息技术有限公司 | N39: CTO | O39: 标准会员 | P39: 188 | S39: - | T39: - | U39: 0 | AE39: alan.chen@linkedcare.cn
A40: 39 | B40: 42559 | C40: 46203 | D40: 黄伟坚 | E40: 男 | G40: 暂无 | I40: 暂无 | J40: １ | K40: 广州 | L40: 1 | M40: mobvista汇量科技 | N40: 联合创始人 | O40: 标准会员 | P40: 190 | S40: - | T40: - | U40: 1 | Y40: 1 | AE40: hwjian@126.com
...

Sheet 会员总表（副本）
A1: 序号 | B1: 加入时间 | C1: 会籍时间 | D1: 姓名 | E1: 性别 | F1: 面试官 | G1: 推荐人 | H1: 推荐大类 | I1: 是否更新 | J1: 地区 | K1: 所在位置 | L1: 公司 | M1: 职位 | N1: 会员类型 | O1: 会员编号 | P1: 是否入组 | Q1: 新会员接待 | R1: 新会员培训时间 | S1: 上线官网 | T1: 新学员见面直播 | U1: 是否续费 | V1: 备注 | W1: 出海 | X1: 加入时长 | Y1: 过期 | Z1: 续费金额 | AA1: 推荐人 | AB1: 推荐大类 | AC1: 邮箱 | AD1: 备注
A2: =ROW()-1 -> 1 | B2: 42129 | C2: 46203 | D2: 艾芙（徐雁斐） | E2: 女 | I2: 1 | J2: 深圳 | L2: 暂无 | M2: 暂无 | N2: 标准会员 | O2: 1 | S2: 1 | X2: =DATEDIF(B2,"2025-6-30","y") -> 10 | AC2: elfe1021@gmail.com
A3: =ROW()-1 -> 2 | B3: 42132 | C3: 46203 | D3: 郭理靖 | E3: 男 | I3: 1 | J3: 杭州 | L3: 奈雪的茶 | M3: CTO | N3: 标准会员 | O3: 2 | R3: - | S3: 1 | V3: 1 | W3: 1 | X3: =DATEDIF(B3,"2025-6-30","y") -> 10 | AC3: guolijing@gmail.com
A4: =ROW()-1 -> 3 | B4: 42139 | C4: 46203 | D4: 陈锡言 | E4: 男 | I4: 无信息0 | J4: 北京 | L4: 一览科技 | M4: CTO | N4: 标准会员 | O4: 5 | P4: 北京0组 | Q4: 0 | R4: - | S4: 1 | W4: 1 | X4: =DATEDIF(B4,"2025-6-30","y") -> 10 | Z4: 已续费 | AC4: cccsmoking@sina.com
A5: =ROW()-1 -> 4 | B5: 42146 | C5: 46203 | D5: 汪威 | E5: 男 | I5: 1 | J5: 北京 | L5: 摩点众筹 | M5: 技术总监 | N5: 高级会员 | O5: 12 | P5: 北京0组 | Q5: 0 | R5: 45120 | S5: 1 | W5: 1 | X5: =DATEDIF(B5,"2025-6-30","y") -> 10 | Z5: 已续费 | AC5: wangcash@gmail.com
A6: =ROW()-1 -> 5 | B6: 42147 | C6: 46203 | D6: 唐小浙 | E6: 男 | I6: 1 | J6: 上海 | L6: 墨誉科技 | M6: 技术vp | N6: 标准会员 | O6: 13 | R6: - | S6: 1 | W6: 1 | X6: =DATEDIF(B6,"2025-6-30","y") -> 10 | AC6: tangxz@gmail.com
A7: =ROW()-1 -> 6 | B7: 42150 | C7: 46203 | D7: 邹光先 | E7: 男 | I7: 0 | J7: 广州 | L7: 其他 | M7: 其他 | N7: 标准会员 | O7: 14 | R7: - | S7: 1 | W7: 1 | X7: =DATEDIF(B7,"2025-6-30","y") -> 10 | AC7: zouguangxian@163.com
A8: =ROW()-1 -> 7 | B8: 42160 | C8: 46203 | D8: 黄良懿 | E8: 男 | I8: 1 | J8: 深圳 | L8: 高仙机器人 | M8: 研发VP | N8: 标准会员 | O8: 17 | R8: - | S8: 1 | W8: 1 | X8: =DATEDIF(B8,"2025-6-30","y") -> 10 | AC8: codeant@hotmail.com
A9: =ROW()-1 -> 8 | B9: 42171 | C9: 46203 | D9: 史海峰 | E9: 男 | I9: 1 | J9: 北京 | L9: 方正证券 | M9: 架构平台负责人 | N9: 标准会员 | O9: 23 | P9: 北京2组 | Q9: 0 | R9: - | S9: 1 | V9: 1 | W9: 1 | X9: =DATEDIF(B9,"2025-6-30","y") -> 10 | Z9: 已续费 | AC9: shihf_dc@163.com
A10: =ROW()-1 -> 9 | B10: 42180 | C10: 46203 | D10: 梁宇鹏 | E10: 男 | I10: 0 | J10: 北京 | L10: 蓝莺IM | M10: CEO | N10: 标准会员 | O10: 24 | P10: 北京2组 | Q10: 0 | R10: - | S10: 1 | W10: 1 | X10: =DATEDIF(B10,"2025-6-30","y") -> 10 | Z10: 已续费 | AC10: eric.l.2046@gmail.com
A11: =ROW()-1 -> 10 | B11: 42202 | C11: 46203 | D11: 熊昌伟 | E11: 男 | I11: 1 | J11: 北京 | L11: 畅捷通信息技术股份有限公司 | M11: 助理总裁 | N11: 标准会员 | O11: 29 | P11: 北京0组 | Q11: 0 | R11: - | S11: 1 | W11: 1 | X11: =DATEDIF(B11,"2025-6-30","y") -> 9 | Z11: 已续费 | AC11: xcw@chanjet.com
A12: =ROW()-1 -> 11 | B12: 42209 | C12: 46203 | D12: 丁宁 | E12: 男 | I12: 无公司 | J12: 新加坡 | L12: 荔枝集团 | M12: CTO | N12: 高级会员 | O12: 30 | R12: 45154 | S12: 1 | V12: 1 | W12: 1 | X12: =DATEDIF(B12,"2025-6-30","y") -> 9 | AC12: dingning@lizhi.fm
A13: =ROW()-1 -> 12 | B13: 42219 | C13: 46203 | D13: 陈靖华 | E13: 男 | I13: 1 | J13: 北京 | L13: 基调听云 | M13: 产品VP | N13: 标准会员 | O13: 34 | P13: 北京2组 | Q13: 0 | R13: - | S13: 1 | W13: 1 | X13: =DATEDIF(B13,"2025-6-30","y") -> 9 | Z13: 已续费 | AC13: wood@tingyun.com
A14: =ROW()-1 -> 13 | B14: 42221 | C14: 46203 | D14: 侯冬雯 | E14: 女 | I14: 无公司 | J14: 北京 | L14: 北京微梦传媒股份有限公司 | M14: CTO | N14: 高级会员 | O14: 38 | P14: 北京0组 | Q14: 0 | R14: - | S14: 1 | W14: 1 | X14: =DATEDIF(B14,"2025-6-30","y") -> 9 | Z14: 已续费 | AC14: dongwen@microdreams.com.cn
A15: =ROW()-1 -> 14 | B15: 42246 | C15: 46203 | D15: 黄彬彬 | E15: 男 | I15: 1 | J15: 上海 | L15: 多云转晴 | M15: 架构师 | N15: 高级会员 | O15: 44 | R15: - | S15: 1 | W15: 1 | X15: =DATEDIF(B15,"2025-6-30","y") -> 9 | AC15: 118733@qq.com
A16: =ROW()-1 -> 15 | B16: 42248 | C16: 46203 | D16: 王立博 | E16: 男 | I16: 1 | J16: 上海 | L16: 未来保贝 | M16: 合伙人&CTO | N16: 标准会员 | O16: 48 | R16: - | S16: 1 | W16: 1 | X16: =DATEDIF(B16,"2025-6-30","y") -> 9 | AC16: w803007@163.com
A17: =ROW()-1 -> 16 | B17: 42256 | C17: 46203 | D17: 胡震 | E17: 男 | I17: 1 | J17: 上海 | L17: 某公链基金会 | M17: 投研负责人 | N17: 标准会员 | O17: 58 | R17: - | S17: 1 | W17: 1 | X17: =DATEDIF(B17,"2025-6-30","y") -> 9 | AC17: huzhencn@163.com
A18: =ROW()-1 -> 17 | B18: 42275 | C18: 46203 | D18: 洪强宁 | E18: 男 | I18: 1 | J18: 北京 | L18: 雅识科技联合 | M18: 创始人兼CTO | N18: 标准会员 | O18: 65 | P18: 北京2组 | Q18: 0 | R18: - | S18: 1 | W18: 1 | X18: =DATEDIF(B18,"2025-6-30","y") -> 9 | Z18: 已续费 | AC18: hongqn@gmail.com
A19: =ROW()-1 -> 18 | B19: 42298 | C19: 46203 | D19: 李道兵 | E19: 男 | I19: 1 | J19: 北京 | L19: Principal Embedded Software Developer | M19: 未登记 | N19: 标准会员 | O19: 70 | P19: 北京13组 | Q19: 0 | R19: - | S19: 1 | W19: 1 | X19: =DATEDIF(B19,"2025-6-30","y") -> 9 | Z19: 无需续费 | AC19: lidaobing@gmail.com
A20: =ROW()-1 -> 19 | B20: 42300 | C20: 46203 | D20: 张海龙 | E20: 男 | I20: 1 | J20: 苏州 | L20: 同程旅行 | M20: 技术委员会主任 | N20: 标准会员 | O20: 72 | R20: - | S20: 1 | V20: 1 | W20: 1 | X20: =DATEDIF(B20,"2025-6-30","y") -> 9 | AC20: zhanghailong@coding.net
A21: =ROW()-1 -> 20 | B21: 42300 | C21: 46203 | D21: 王晓波 | E21: 男 | I21: 0 | J21: 苏州 | L21: 同程旅行 | M21: AVP&出行事业群 CTO | N21: 标准会员 | O21: 71 | R21: - | S21: 1 | W21: 1 | X21: =DATEDIF(B21,"2025-6-30","y") -> 9 | AC21: wxb09195@ly.com
A22: =ROW()-1 -> 21 | B22: 42318 | C22: 46203 | D22: 林华根 | E22: 男 | I22: 1 | J22: 深圳 | L22: 安徽超远信息技术有限公司 | M22: 副总工程师 | N22: 标准会员 | O22: 78 | R22: - | S22: 1 | W22: 1 | X22: =DATEDIF(B22,"2025-6-30","y") -> 9 | AC22: lhg@cychina.cn
A23: =ROW()-1 -> 22 | B23: 42334 | C23: 46203 | D23: 魏吉贺 | E23: 男 | I23: 1 | J23: 深圳 | L23: 深圳市残友软件股份有限公司 | M23: 技术总监 | N23: 标准会员 | O23: 91 | R23: - | S23: 1 | W23: 1 | X23: =DATEDIF(B23,"2025-6-30","y") -> 9 | AC23: wjh@canyou.cn
A24: =ROW()-1 -> 23 | B24: 42339 | C24: 46203 | D24: 龚银 | E24: 男 | I24: 1 | J24: 深圳 | L24: 安克创新 | M24: CIO | N24: 标准会员 | O24: 95 | R24: - | S24: 1 | W24: 1 | X24: =DATEDIF(B24,"2025-6-30","y") -> 9 | AC24: gongyin@126.com
A25: =ROW()-1 -> 24 | B25: 42361 | C25: 46203 | D25: 华健 | E25: 男 | I25: 1 | J25: 北京 | L25: 梦诚科技 | M25: 创始人&CTO | N25: 标准会员 | O25: 102 | P25: 北京2组 | Q25: 0 | R25: - | S25: 1 | W25: 1 | X25: =DATEDIF(B25,"2025-6-30","y") -> 9 | Z25: 已续费 | AC25: huaj1101@qq.com
A26: =ROW()-1 -> 25 | B26: 42427 | C26: 46203 | D26: 何世友 | E26: 男 | I26: 1 | J26: 广州 | L26: 腾讯云 | M26: Serverless 产品负责人 | N26: 标准会员 | O26: 114 | R26: - | S26: 1 | W26: 1 | X26: =DATEDIF(B26,"2025-6-30","y") -> 9 | AC26: shiyou.he@gmail.com
A27: =ROW()-1 -> 26 | B27: 42433 | C27: 46203 | D27: 李玉福 | E27: 男 | I27: 1 | J27: 北京 | L27: 北京农信互联科技有限公司 | M27: 副总裁 | N27: 标准会员 | O27: 117 | P27: 北京15组 | Q27: 0 | R27: - | S27: 1 | W27: 1 | X27: =DATEDIF(B27,"2025-6-30","y") -> 9 | Z27: 已续费 | AC27: liyufu@nxin.com
A28: =ROW()-1 -> 27 | B28: 42451 | C28: 46203 | D28: 曾冠东 | E28: 男 | I28: 0 | J28: 广州 | L28: 酷狗音乐 | M28: 繁星网研发总监 | N28: 标准会员 | O28: 123 | R28: - | S28: 1 | V28: 1 | W28: 1 | X28: =DATEDIF(B28,"2025-6-30","y") -> 9 | AC28: popeast@gmail.com
A29: =ROW()-1 -> 28 | B29: 42451 | C29: 46203 | D29: 路文杰 | E29: 男 | I29: 1 | J29: 广州 | L29: 甘果科技 | M29: CEO | N29: 标准会员 | O29: 121 | R29: - | S29: 1 | X29: =DATEDIF(B29,"2025-6-30","y") -> 9 | AC29: cngump@gmail.com
A30: =ROW()-1 -> 29 | B30: 42473 | C30: 46203 | D30: 高楚涛 | E30: 男 | I30: 1 | J30: 深圳 | L30: 深圳市嘉立创科技发展有限公司 | M30: CIO | N30: 标准会员 | O30: 135 | R30: - | S30: 1 | W30: 1 | X30: =DATEDIF(B30,"2025-6-30","y") -> 9 | AC30: gaochutao@163.com
A31: =ROW()-1 -> 30 | B31: 42480 | C31: 46203 | D31: 刘建国 | E31: 男 | I31: 1 | J31: 广州 | K31: 1 | L31: 伊智信息科技 | M31: CEO | N31: 标准会员 | O31: 26 | R31: - | S31: 1 | W31: 1 | X31: =DATEDIF(B31,"2025-6-30","y") -> 9 | AC31: yijshu@gmail.com
A32: =ROW()-1 -> 31 | B32: 42482 | C32: 46203 | D32: 万林涛 | E32: 男 | I32: 1 | J32: 上海 | L32: 上海蔚星数据 | M32: 副总裁兼首席数据官 | N32: 标准会员 | O32: 140 | R32: - | S32: 1 | W32: 1 | X32: =DATEDIF(B32,"2025-6-30","y") -> 9 | AC32: lintao.wan@outlook.com
A33: =ROW()-1 -> 32 | B33: 42482 | C33: 46203 | D33: 徐翎 | E33: 男 | I33: 1 | J33: 上海 | L33: 上海数达物流科技有限公司 | M33: CTO | N33: 标准会员 | O33: 139 | R33: - | S33: 1 | X33: =DATEDIF(B33,"2025-6-30","y") -> 9 | AC33: xlshcn@hotmail.com
A34: =ROW()-1 -> 33 | B34: 42495 | C34: 46203 | D34: 肖颖 | E34: 男 | I34: １ | J34: 上海 | L34: 上海澄廓信息科技有限公司 | M34: CEO | N34: 标准会员 | O34: 144 | R34: - | S34: 1 | X34: =DATEDIF(B34,"2025-6-30","y") -> 9 | AC34: 18049722632@163.com
A35: =ROW()-1 -> 34 | B35: 42524 | C35: 46203 | D35: 张剑伟 | E35: 男 | I35: １ | J35: 上海 | L35: 百安居 | M35: CTO | N35: 标准会员 | O35: 160 | R35: - | S35: 1 | X35: =DATEDIF(B35,"2025-6-30","y") -> 9 | AC35: zjwsoft@gmail.com
A36: =ROW()-1 -> 35 | B36: 42536 | C36: 46203 | D36: 苏煦烽 | E36: 男 | I36: １ | J36: 广州 | K36: 1 | L36: 亲邻科技 | M36: 技术总监 | N36: 标准会员 | O36: 167 | R36: - | S36: 1 | W36: 1 | X36: =DATEDIF(B36,"2025-6-30","y") -> 9 | AC36: suxufeng@qq.com
A37: =ROW()-1 -> 36 | B37: 42537 | C37: 46203 | D37: 孙其瑞 | E37: 男 | I37: １ | J37: 杭州 | L37: 苏州优频科技有限公司 | M37: CTO | N37: 标准会员 | O37: 171 | R37: - | S37: 1 | W37: 1 | X37: =DATEDIF(B37,"2025-6-30","y") -> 9 | AC37: sqr@detu.com
A38: =ROW()-1 -> 37 | B38: 42552 | C38: 46203 | D38: 芦宇峰 | E38: 男 | I38: １ | J38: 杭州 | L38: 上海擎路科技 | M38: 联合创始人 & CTO | N38: 标准会员 | O38: 178 | R38: - | S38: 1 | W38: 1 | X38: =DATEDIF(B38,"2025-6-30","y") -> 8 | AC38: xiao_ys@163.com
A39: =ROW()-1 -> 38 | B39: 42556 | C39: 46203 | D39: 陈杰 | E39: 男 | I39: １ | J39: 上海 | L39: 上海领健信息技术有限公司 | M39: CTO | N39: 标准会员 | O39: 188 | R39: - | S39: 0 | X39: =DATEDIF(B39,"2025-6-30","y") -> 8 | AC39: alan.chen@linkedcare.cn
A40: =ROW()-1 -> 39 | B40: 42559 | C40: 46203 | D40: 黄伟坚 | E40: 男 | I40: １ | J40: 广州 | K40: 1 | L40: mobvista汇量科技 | M40: 联合创始人 | N40: 标准会员 | O40: 190 | R40: - | S40: 1 | W40: 1 | X40: =DATEDIF(B40,"2025-6-30","y") -> 8 | AC40: hwjian@126.com
...

Sheet 会员推荐
A1: 加入时间 - 年份 | B1: (全部)
A2: 加入时间 - 月份 | B2: (全部)
A4: 推荐人 | B4: 地区 | C4: 计数:姓名
A5: 暂无 | B5: 北京 | C5: 157
A6: 暂无 汇总 | C6: 157
A7: 杨攀 | B7: 北京 | C7: 17
A8: 杨攀 汇总 | C8: 17
A9: infoQ | B9: 北京 | C9: 12
A10: infoQ 汇总 | C10: 12
A11: 郭子龙 | B11: 北京 | C11: 7
A12: 郭子龙 汇总 | C12: 7
A13: 陈肃 | B13: 北京 | C13: 5
A14: 陈肃 汇总 | C14: 5
A15: Kevin | B15: 北京 | C15: 5
A16: Kevin 汇总 | C16: 5
A17: 高驰涛 | B17: 北京 | C17: 4
A18: 高驰涛 汇总 | C18: 4
A19: 裴晟 | B19: 北京 | C19: 4
A20: 裴晟 汇总 | C20: 4
A21: 宜博 | B21: 北京 | C21: 4
A22: 宜博 汇总 | C22: 4
A23: 自然流量-官网 | B23: 北京 | C23: 4
A24: 自然流量-官网 汇总 | C24: 4
A25: 杨扬 | B25: 北京 | C25: 3
A26: 杨扬 汇总 | C26: 3
A27: 于游 | B27: 北京 | C27: 3
A28: 于游 汇总 | C28: 3
A29: 王电轻 | B29: 北京 | C29: 3
A30: 王电轻 汇总 | C30: 3
A31: GTLC | B31: 北京 | C31: 3
A32: GTLC 汇总 | C32: 3
A33: 自然流量-朋友 | B33: 北京 | C33: 3
A34: 自然流量-朋友 汇总 | C34: 3
A35: 郭炜 | B35: 北京 | C35: 3
A36: 郭炜 汇总 | C36: 3
A37: 梁宇鹏 | B37: 北京 | C37: 2
A38: 梁宇鹏 汇总 | C38: 2
A39: 唐春林 | B39: 北京 | C39: 2
A40: 唐春林 汇总 | C40: 2
A41: 陈靖华 | B41: 北京 | C41: 2
...

Sheet 26年续费-含十年
A1: 序号 | B1: 加入时间 | C1: 会籍时间 | D1: 姓名 | E1: 性别 | F1: 是否更新 | G1: 地区 | H1: 所在位置 | I1: 公司 | J1: 职位 | K1: 会员类型 | L1: 续费金额 | M1: 会员编号 | N1: 是否入组 | O1: 新会员培训时间 | P1: 上线官网 | Q1: 新学员见面直播 | R1: 是否续费 | S1: 备注 | T1: 出海 | U1: 加入时长 | V1: 过期 | W1: 续费金额 | X1: 推荐人 | Y1: 推荐大类 | Z1: 邮箱 | AA1: 备注
A2: =ROW()-1 -> 1 | B2: 42129 | C2: 46203 | D2: 艾芙（徐雁斐） | E2: 女 | F2: 1 | G2: 深圳 | I2: 暂无 | J2: 暂无 | K2: 标准会员 | M2: 1 | P2: 1 | U2: =DATEDIF(B2,"2025-6-30","y") -> 10 | Z2: elfe1021@gmail.com
A3: =ROW()-1 -> 2 | B3: 42132 | C3: 46203 | D3: 郭理靖 | E3: 男 | F3: 1 | G3: 杭州 | I3: 奈雪的茶 | J3: CTO | K3: 标准会员 | M3: 2 | O3: - | P3: 1 | S3: 1 | T3: 1 | U3: =DATEDIF(B3,"2025-6-30","y") -> 10 | Z3: guolijing@gmail.com
A4: =ROW()-1 -> 3 | B4: 42139 | C4: 46203 | D4: 陈锡言 | E4: 男 | F4: 无信息0 | G4: 北京 | I4: 一览科技 | J4: CTO | K4: 标准会员 | M4: 5 | N4: 北京0组 | O4: - | P4: 1 | T4: 1 | U4: =DATEDIF(B4,"2025-6-30","y") -> 10 | W4: 已续费 | Z4: cccsmoking@sina.com
A5: =ROW()-1 -> 4 | B5: 42146 | C5: 46203 | D5: 汪威 | E5: 男 | F5: 1 | G5: 北京 | I5: 摩点众筹 | J5: 技术总监 | K5: 高级会员 | M5: 12 | N5: 北京0组 | O5: 45120 | P5: 1 | T5: 1 | U5: =DATEDIF(B5,"2025-6-30","y") -> 10 | W5: 已续费 | Z5: wangcash@gmail.com
A6: =ROW()-1 -> 5 | B6: 42147 | C6: 46203 | D6: 唐小浙 | E6: 男 | F6: 1 | G6: 上海 | I6: 墨誉科技 | J6: 技术vp | K6: 标准会员 | M6: 13 | O6: - | P6: 1 | T6: 1 | U6: =DATEDIF(B6,"2025-6-30","y") -> 10 | Z6: tangxz@gmail.com
A7: =ROW()-1 -> 6 | B7: 42150 | C7: 46203 | D7: 邹光先 | E7: 男 | F7: 0 | G7: 广州 | I7: 其他 | J7: 其他 | K7: 标准会员 | M7: 14 | O7: - | P7: 1 | T7: 1 | U7: =DATEDIF(B7,"2025-6-30","y") -> 10 | Z7: zouguangxian@163.com
A8: =ROW()-1 -> 7 | B8: 42160 | C8: 46203 | D8: 黄良懿 | E8: 男 | F8: 1 | G8: 深圳 | I8: 高仙机器人 | J8: 研发VP | K8: 标准会员 | M8: 17 | O8: - | P8: 1 | T8: 1 | U8: =DATEDIF(B8,"2025-6-30","y") -> 10 | Z8: codeant@hotmail.com
A9: =ROW()-1 -> 8 | B9: 42171 | C9: 46203 | D9: 史海峰 | E9: 男 | F9: 1 | G9: 北京 | I9: 方正证券 | J9: 架构平台负责人 | K9: 标准会员 | M9: 23 | N9: 北京2组 | O9: - | P9: 1 | S9: 1 | T9: 1 | U9: =DATEDIF(B9,"2025-6-30","y") -> 10 | W9: 已续费 | Z9: shihf_dc@163.com
A10: =ROW()-1 -> 9 | B10: 42180 | C10: 46203 | D10: 梁宇鹏 | E10: 男 | F10: 0 | G10: 北京 | I10: 蓝莺IM | J10: CEO | K10: 标准会员 | M10: 24 | N10: 北京2组 | O10: - | P10: 1 | T10: 1 | U10: =DATEDIF(B10,"2025-6-30","y") -> 10 | W10: 已续费 | Z10: eric.l.2046@gmail.com
A11: =ROW()-1 -> 10 | B11: 42202 | C11: 46203 | D11: 熊昌伟 | E11: 男 | F11: 1 | G11: 北京 | I11: 畅捷通信息技术股份有限公司 | J11: 助理总裁 | K11: 标准会员 | M11: 29 | N11: 北京0组 | O11: - | P11: 1 | T11: 1 | U11: =DATEDIF(B11,"2025-6-30","y") -> 9 | W11: 已续费 | Z11: xcw@chanjet.com
A12: =ROW()-1 -> 11 | B12: 42209 | C12: 46203 | D12: 丁宁 | E12: 男 | F12: 无公司 | G12: 新加坡 | I12: 荔枝集团 | J12: CTO | K12: 高级会员 | M12: 30 | O12: 45154 | P12: 1 | S12: 1 | T12: 1 | U12: =DATEDIF(B12,"2025-6-30","y") -> 9 | Z12: dingning@lizhi.fm
A13: =ROW()-1 -> 12 | B13: 42219 | C13: 46203 | D13: 陈靖华 | E13: 男 | F13: 1 | G13: 北京 | I13: 基调听云 | J13: 产品VP | K13: 标准会员 | M13: 34 | N13: 北京2组 | O13: - | P13: 1 | T13: 1 | U13: =DATEDIF(B13,"2025-6-30","y") -> 9 | W13: 已续费 | Z13: wood@tingyun.com
A14: =ROW()-1 -> 13 | B14: 42221 | C14: 46203 | D14: 侯冬雯 | E14: 女 | F14: 无公司 | G14: 北京 | I14: 北京微梦传媒股份有限公司 | J14: CTO | K14: 高级会员 | M14: 38 | N14: 北京0组 | O14: - | P14: 1 | T14: 1 | U14: =DATEDIF(B14,"2025-6-30","y") -> 9 | W14: 已续费 | Z14: dongwen@microdreams.com.cn
A15: =ROW()-1 -> 14 | B15: 42246 | C15: 46203 | D15: 黄彬彬 | E15: 男 | F15: 1 | G15: 上海 | I15: 多云转晴 | J15: 架构师 | K15: 高级会员 | M15: 44 | O15: - | P15: 1 | T15: 1 | U15: =DATEDIF(B15,"2025-6-30","y") -> 9 | Z15: 118733@qq.com
A16: =ROW()-1 -> 15 | B16: 42248 | C16: 46203 | D16: 王立博 | E16: 男 | F16: 1 | G16: 上海 | I16: 未来保贝 | J16: 合伙人&CTO | K16: 标准会员 | M16: 48 | O16: - | P16: 1 | T16: 1 | U16: =DATEDIF(B16,"2025-6-30","y") -> 9 | Z16: w803007@163.com
A17: =ROW()-1 -> 16 | B17: 42256 | C17: 46203 | D17: 胡震 | E17: 男 | F17: 1 | G17: 上海 | I17: 某公链基金会 | J17: 投研负责人 | K17: 标准会员 | M17: 58 | O17: - | P17: 1 | T17: 1 | U17: =DATEDIF(B17,"2025-6-30","y") -> 9 | Z17: huzhencn@163.com
A18: =ROW()-1 -> 17 | B18: 42275 | C18: 46203 | D18: 洪强宁 | E18: 男 | F18: 1 | G18: 北京 | I18: 雅识科技联合 | J18: 创始人兼CTO | K18: 标准会员 | M18: 65 | N18: 北京2组 | O18: - | P18: 1 | T18: 1 | U18: =DATEDIF(B18,"2025-6-30","y") -> 9 | W18: 已续费 | Z18: hongqn@gmail.com
A19: =ROW()-1 -> 18 | B19: 42298 | C19: 46203 | D19: 李道兵 | E19: 男 | F19: 1 | G19: 北京 | I19: Principal Embedded Software Developer | J19: 未登记 | K19: 标准会员 | M19: 70 | N19: 北京13组 | O19: - | P19: 1 | T19: 1 | U19: =DATEDIF(B19,"2025-6-30","y") -> 9 | W19: 无需续费 | Z19: lidaobing@gmail.com
A20: =ROW()-1 -> 19 | B20: 42300 | C20: 46203 | D20: 张海龙 | E20: 男 | F20: 1 | G20: 苏州 | I20: 同程旅行 | J20: 技术委员会主任 | K20: 标准会员 | M20: 72 | O20: - | P20: 1 | S20: 1 | T20: 1 | U20: =DATEDIF(B20,"2025-6-30","y") -> 9 | Z20: zhanghailong@coding.net
A21: =ROW()-1 -> 20 | B21: 42300 | C21: 46203 | D21: 王晓波 | E21: 男 | F21: 0 | G21: 苏州 | I21: 同程旅行 | J21: AVP&出行事业群 CTO | K21: 标准会员 | M21: 71 | O21: - | P21: 1 | T21: 1 | U21: =DATEDIF(B21,"2025-6-30","y") -> 9 | Z21: wxb09195@ly.com
A22: =ROW()-1 -> 21 | B22: 42318 | C22: 46203 | D22: 林华根 | E22: 男 | F22: 1 | G22: 深圳 | I22: 安徽超远信息技术有限公司 | J22: 副总工程师 | K22: 标准会员 | M22: 78 | O22: - | P22: 1 | T22: 1 | U22: =DATEDIF(B22,"2025-6-30","y") -> 9 | Z22: lhg@cychina.cn
A23: =ROW()-1 -> 22 | B23: 42334 | C23: 46203 | D23: 魏吉贺 | E23: 男 | F23: 1 | G23: 深圳 | I23: 深圳市残友软件股份有限公司 | J23: 技术总监 | K23: 标准会员 | M23: 91 | O23: - | P23: 1 | T23: 1 | U23: =DATEDIF(B23,"2025-6-30","y") -> 9 | Z23: wjh@canyou.cn
A24: =ROW()-1 -> 23 | B24: 42339 | C24: 46203 | D24: 龚银 | E24: 男 | F24: 1 | G24: 深圳 | I24: 安克创新 | J24: CIO | K24: 标准会员 | M24: 95 | O24: - | P24: 1 | T24: 1 | U24: =DATEDIF(B24,"2025-6-30","y") -> 9 | Z24: gongyin@126.com
A25: =ROW()-1 -> 24 | B25: 42361 | C25: 46203 | D25: 华健 | E25: 男 | F25: 1 | G25: 北京 | I25: 梦诚科技 | J25: 创始人&CTO | K25: 标准会员 | M25: 102 | N25: 北京2组 | O25: - | P25: 1 | T25: 1 | U25: =DATEDIF(B25,"2025-6-30","y") -> 9 | W25: 已续费 | Z25: huaj1101@qq.com
A26: =ROW()-1 -> 25 | B26: 42427 | C26: 46203 | D26: 何世友 | E26: 男 | F26: 1 | G26: 广州 | I26: 腾讯云 | J26: Serverless 产品负责人 | K26: 标准会员 | M26: 114 | O26: - | P26: 1 | T26: 1 | U26: =DATEDIF(B26,"2025-6-30","y") -> 9 | Z26: shiyou.he@gmail.com
A27: =ROW()-1 -> 26 | B27: 42433 | C27: 46203 | D27: 李玉福 | E27: 男 | F27: 1 | G27: 北京 | I27: 北京农信互联科技有限公司 | J27: 副总裁 | K27: 标准会员 | M27: 117 | N27: 北京13组 | O27: - | P27: 1 | T27: 1 | U27: =DATEDIF(B27,"2025-6-30","y") -> 9 | W27: 已续费 | Z27: liyufu@nxin.com
A28: =ROW()-1 -> 27 | B28: 42451 | C28: 46203 | D28: 曾冠东 | E28: 男 | F28: 0 | G28: 广州 | I28: 酷狗音乐 | J28: 繁星网研发总监 | K28: 标准会员 | M28: 123 | O28: - | P28: 1 | S28: 1 | T28: 1 | U28: =DATEDIF(B28,"2025-6-30","y") -> 9 | Z28: popeast@gmail.com
A29: =ROW()-1 -> 28 | B29: 42451 | C29: 46203 | D29: 路文杰 | E29: 男 | F29: 1 | G29: 广州 | I29: 甘果科技 | J29: CEO | K29: 标准会员 | M29: 121 | O29: - | P29: 1 | U29: =DATEDIF(B29,"2025-6-30","y") -> 9 | Z29: cngump@gmail.com
A30: =ROW()-1 -> 29 | B30: 42473 | C30: 46203 | D30: 高楚涛 | E30: 男 | F30: 1 | G30: 深圳 | I30: 深圳市嘉立创科技发展有限公司 | J30: CIO | K30: 标准会员 | M30: 135 | O30: - | P30: 1 | T30: 1 | U30: =DATEDIF(B30,"2025-6-30","y") -> 9 | Z30: gaochutao@163.com
A31: =ROW()-1 -> 30 | B31: 42480 | C31: 46203 | D31: 刘建国 | E31: 男 | F31: 1 | G31: 广州 | H31: 1 | I31: 伊智信息科技 | J31: CEO | K31: 标准会员 | M31: 26 | O31: - | P31: 1 | T31: 1 | U31: =DATEDIF(B31,"2025-6-30","y") -> 9 | Z31: yijshu@gmail.com
A32: =ROW()-1 -> 31 | B32: 42482 | C32: 46203 | D32: 万林涛 | E32: 男 | F32: 1 | G32: 上海 | I32: 上海蔚星数据 | J32: 副总裁兼首席数据官 | K32: 标准会员 | M32: 140 | O32: - | P32: 1 | T32: 1 | U32: =DATEDIF(B32,"2025-6-30","y") -> 9 | Z32: lintao.wan@outlook.com
A33: =ROW()-1 -> 32 | B33: 42482 | C33: 46203 | D33: 徐翎 | E33: 男 | F33: 1 | G33: 上海 | I33: 上海数达物流科技有限公司 | J33: CTO | K33: 标准会员 | M33: 139 | O33: - | P33: 1 | U33: =DATEDIF(B33,"2025-6-30","y") -> 9 | Z33: xlshcn@hotmail.com
A34: =ROW()-1 -> 33 | B34: 42495 | C34: 46203 | D34: 肖颖 | E34: 男 | F34: １ | G34: 上海 | I34: 上海澄廓信息科技有限公司 | J34: CEO | K34: 标准会员 | M34: 144 | O34: - | P34: 1 | U34: =DATEDIF(B34,"2025-6-30","y") -> 9 | Z34: 18049722632@163.com
A35: =ROW()-1 -> 34 | B35: 42524 | C35: 46203 | D35: 张剑伟 | E35: 男 | F35: １ | G35: 上海 | I35: 百安居 | J35: CTO | K35: 标准会员 | M35: 160 | O35: - | P35: 1 | U35: =DATEDIF(B35,"2025-6-30","y") -> 9 | Z35: zjwsoft@gmail.com
A36: =ROW()-1 -> 35 | B36: 42536 | C36: 46203 | D36: 苏煦烽 | E36: 男 | F36: １ | G36: 广州 | H36: 1 | I36: 亲邻科技 | J36: 技术总监 | K36: 标准会员 | M36: 167 | O36: - | P36: 1 | T36: 1 | U36: =DATEDIF(B36,"2025-6-30","y") -> 9 | Z36: suxufeng@qq.com
A37: =ROW()-1 -> 36 | B37: 42537 | C37: 46203 | D37: 孙其瑞 | E37: 男 | F37: １ | G37: 杭州 | I37: 苏州优频科技有限公司 | J37: CTO | K37: 标准会员 | M37: 171 | O37: - | P37: 1 | T37: 1 | U37: =DATEDIF(B37,"2025-6-30","y") -> 9 | Z37: sqr@detu.com
A38: =ROW()-1 -> 37 | B38: 42552 | C38: 46203 | D38: 芦宇峰 | E38: 男 | F38: １ | G38: 杭州 | I38: 上海擎路科技 | J38: 联合创始人 & CTO | K38: 标准会员 | M38: 178 | O38: - | P38: 1 | T38: 1 | U38: =DATEDIF(B38,"2025-6-30","y") -> 8 | Z38: xiao_ys@163.com
A39: =ROW()-1 -> 38 | B39: 42556 | C39: 46203 | D39: 陈杰 | E39: 男 | F39: １ | G39: 上海 | I39: 上海领健信息技术有限公司 | J39: CTO | K39: 标准会员 | M39: 188 | O39: - | P39: 0 | U39: =DATEDIF(B39,"2025-6-30","y") -> 8 | Z39: alan.chen@linkedcare.cn
A40: =ROW()-1 -> 39 | B40: 42559 | C40: 46203 | D40: 黄伟坚 | E40: 男 | F40: １ | G40: 广州 | H40: 1 | I40: mobvista汇量科技 | J40: 联合创始人 | K40: 标准会员 | M40: 190 | O40: - | P40: 1 | T40: 1 | U40: =DATEDIF(B40,"2025-6-30","y") -> 8 | Z40: hwjian@126.com
...

Sheet 26年续费底表-不含十年
A1: 序号 | B1: 加入时间 | C1: 会籍时间 | D1: 姓名 | E1: 性别 | F1: 是否更新 | G1: 地区 | H1: 所在位置 | I1: 公司 | J1: 职位 | K1: 会员类型 | L1: 续费金额 | M1: 会员编号 | N1: 是否入组 | O1: 新会员培训时间 | P1: 上线官网 | Q1: 新学员见面直播 | R1: 是否续费 | S1: 备注 | T1: 出海 | U1: 加入时长 | V1: 过期 | W1: 续费金额 | X1: 推荐人 | Y1: 推荐大类 | Z1: 邮箱 | AA1: 备注
A2: =ROW()-1 -> 1 | B2: 42758 | C2: 46203 | D2: 杨冀龙 | E2: 男 | F2: 0 | G2: 北京 | I2: 北京知道创宇信息技术有限公司 | J2: CTO+COO | K2: 标准会员 | L2: 5400 | M2: 318 | N2: 北京0组 | O2: - | P2: 1 | U2: =DATEDIF(B2,"2025-6-30","y") -> 8 | W2: 已续费 | Z2: yang@knownsec.com
A3: =ROW()-1 -> 2 | B3: 42779 | C3: 46203 | D3: 余峰 | E3: 男 | F3: １ | G3: 北京 | I3: 汉迪科技 | J3: 商业化平台事业部负责人 | K3: 标准会员 | L3: 5400 | M3: 324 | N3: 北京13组 | O3: - | P3: 1 | U3: =DATEDIF(B3,"2025-6-30","y") -> 8 | W3: 已续费 | Z3: feng.yu@ewp-group.com
A4: =ROW()-1 -> 3 | B4: 42783 | C4: 46203 | D4: 林佳齐 | E4: 男 | F4: １ | G4: 杭州 | I4: 西阿爱木 | J4: CEO | K4: 标准会员 | L4: 5400 | M4: 327 | O4: - | P4: 1 | U4: =DATEDIF(B4,"2025-6-30","y") -> 8 | Z4: linjiaqi86@gmail.com
A5: =ROW()-1 -> 4 | B5: 42789 | C5: 46203 | D5: 焦洋 | E5: 男 | F5: １ | G5: 北京 | I5: 盖娅互娱 | J5: CTO | K5: 标准会员 | L5: 5400 | M5: 329 | N5: 北京12组 | O5: - | P5: 1 | S5: 1 | U5: =DATEDIF(B5,"2025-6-30","y") -> 8 | W5: 已续费 | Z5: jiao.yang.bupt@gmail.com
A6: =ROW()-1 -> 5 | B6: 42793 | C6: 46203 | D6: 张觅 | E6: 男 | F6: １ | G6: 北京 | I6: 况客科技 | J6: 技术合伙人 | K6: 标准会员 | L6: 5400 | M6: 332 | N6: 北京13组 | O6: - | P6: 1 | U6: =DATEDIF(B6,"2025-6-30","y") -> 8 | W6: 已续费 | Z6: zhm83@163.com
A7: =ROW()-1 -> 6 | B7: 42800 | C7: 46203 | D7: 陈颖棠 | E7: 男 | F7: １ | G7: 广州 | I7: 论客科技（广州）有限公司 | J7: 首席架构师 | K7: 高级会员 | L7: 9216 | M7: 337 | O7: - | P7: 1 | U7: =DATEDIF(B7,"2025-6-30","y") -> 8 | Z7: cyt@mailtech.cn
A8: =ROW()-1 -> 7 | B8: 42801 | C8: 46203 | D8: 黎宏伟 | E8: 男 | F8: １ | G8: 成都 | I8: 成都市美幻科技有限公司 | J8: 技术总监 | K8: 标准会员 | L8: 5400 | M8: 333 | O8: - | P8: 1 | U8: =DATEDIF(B8,"2025-6-30","y") -> 8 | Z8: lhwdev@qq.com
A9: =ROW()-1 -> 8 | B9: 42807 | C9: 46203 | D9: 李伟辰 | E9: 男 | F9: １ | G9: 北京 | I9: 北京知道创宇信息技术有限公司 | J9: 技术VP | K9: 标准会员 | L9: 5400 | M9: 336 | N9: 北京12组 | O9: - | P9: 1 | U9: =DATEDIF(B9,"2025-6-30","y") -> 8 | W9: 已续费 | Z9: liwc@knownsec.com
A10: =ROW()-1 -> 9 | B10: 42815 | C10: 46203 | D10: 崔浩波 | E10: 男 | F10: １ | G10: 北京 | I10: 北京嗨学网教育科技有限公司 | J10: CTO | K10: 标准会员 | L10: 5400 | M10: 340 | N10: 北京12组 | O10: - | P10: 1 | S10: 1 | U10: =DATEDIF(B10,"2025-6-30","y") -> 8 | W10: 已续费 | Z10: cuihaobo@gmail.com
A11: =ROW()-1 -> 10 | B11: 42838 | C11: 46203 | D11: 任腾 | E11: 男 | F11: １ | G11: 硅谷 | I11: AI Rudder | J11: CEO | K11: 标准会员 | L11: 5400 | M11: 346 | O11: - | P11: 1 | U11: =DATEDIF(B11,"2025-6-30","y") -> 8 | Z11: teng.ren@airudder.com
A12: =ROW()-1 -> 11 | B12: 42839 | C12: 46203 | D12: 李晨丰 | E12: 男 | F12: １ | G12: 深圳 | H12: 1 | I12: 深圳米筐科技有限公司 | J12: COO | K12: 标准会员 | L12: 5400 | M12: 347 | O12: - | P12: 1 | U12: =DATEDIF(B12,"2025-6-30","y") -> 8 | Z12: kangol@ricequant.com
A13: =ROW()-1 -> 12 | B13: 42849 | C13: 46203 | D13: 钱小军 | E13: 男 | F13: １ | G13: 上海 | I13: 安永中国咨询 | J13: 金融科技咨询经理 | K13: 标准会员 | L13: 5400 | M13: 349 | O13: - | P13: 1 | U13: =DATEDIF(B13,"2025-6-30","y") -> 8 | Z13: abelqian@vip.sina.com
A14: =ROW()-1 -> 13 | B14: 42866 | C14: 46203 | D14: 王翱宇 | E14: 男 | F14: １ | G14: 杭州 | I14: 杭州谐云科技有限公司 | J14: CEO | K14: 标准会员 | L14: 5400 | M14: 356 | O14: - | P14: 1 | U14: =DATEDIF(B14,"2025-6-30","y") -> 8 | Z14: way@harmonycloud.cn
A15: =ROW()-1 -> 14 | B15: 42912 | C15: 46203 | D15: 徐庆新 | E15: 男 | F15: １ | G15: 苏州 | I15: 苏州乐佰图信息技术有限公司 | J15: 产品总监 | K15: 标准会员 | L15: 5400 | M15: 3700 | O15: - | P15: 1 | U15: =DATEDIF(B15,"2025-6-30","y") -> 8 | Z15: xuqingxin@gmail.com
A16: =ROW()-1 -> 15 | B16: 42874 | C16: 46203 | D16: 暨家愉 | E16: 男 | F16: １ | G16: 广州 | I16: 腾讯 | J16: 专家架构师 | K16: 标准会员 | L16: 5400 | M16: 361 | O16: - | P16: 1 | S16: 1 | U16: =DATEDIF(B16,"2025-6-30","y") -> 8 | Z16: jiayu.ji@gmail.com
A17: =ROW()-1 -> 16 | B17: 42886 | C17: 46203 | D17: 肖毅 | E17: 男 | F17: １ | G17: 成都 | I17: 成都智客科技有限公司 | J17: CEO | K17: 标准会员 | L17: 5400 | M17: 362 | O17: - | P17: 1 | U17: =DATEDIF(B17,"2025-6-30","y") -> 8 | Z17: xiaoyi@aoasp.com
A18: =ROW()-1 -> 17 | B18: 42927 | C18: 46203 | D18: 曹祖鹏 | E18: 男 | F18: １ | G18: 南京 | I18: 南京知亦行信息技术有限公司 | J18: CTO | K18: 标准会员 | L18: 5400 | M18: 376 | O18: - | P18: 1 | U18: =DATEDIF(B18,"2025-6-30","y") -> 7 | Z18: caozupeng@139.com
A19: =ROW()-1 -> 18 | B19: 42935 | C19: 46203 | D19: 杨振东 | E19: 男 | F19: １ | G19: 上海 | I19: 上海方亿信息科技有限公司 | J19: 联合创始人&CTO | K19: 高级会员 | L19: 9216 | M19: 383 | O19: - | P19: 1 | U19: =DATEDIF(B19,"2025-6-30","y") -> 7 | Z19: yzd@aso360.com
A20: =ROW()-1 -> 19 | B20: 42936 | C20: 46203 | D20: 张志成 | E20: 男 | F20: １ | G20: 杭州 | I20: 阿里巴巴达摩院 | J20: 高级技术专家 | K20: 标准会员 | L20: 5400 | M20: 388 | O20: - | P20: 1 | U20: =DATEDIF(B20,"2025-6-30","y") -> 7 | Z20: zczhang.hvac@gmail.com
A21: =ROW()-1 -> 20 | B21: 42941 | C21: 46203 | D21: 杨红光 | E21: 男 | F21: １ | G21: 北京 | I21: 1Box | J21: CTO | K21: 标准会员 | L21: 5400 | M21: 394 | N21: 北京13组 | O21: - | P21: 1 | U21: =DATEDIF(B21,"2025-6-30","y") -> 7 | W21: 已续费 | Z21: njyhg@163.com
A22: =ROW()-1 -> 21 | B22: 42954 | C22: 46203 | D22: 杨帅麒 | E22: 男 | F22: １ | G22: 上海 | I22: 上海盛大汽车服务集团 | J22: CTO | K22: 标准会员 | L22: 5400 | M22: 402 | O22: - | P22: 1 | R22: 无地址 | U22: =DATEDIF(B22,"2025-6-30","y") -> 7 | Z22: 408482214@qq.com
A23: =ROW()-1 -> 22 | B23: 42957 | C23: 46203 | D23: 胡继伟 | E23: 男 | F23: １ | G23: 北京 | I23: 合思 | J23: 架构师 | K23: 标准会员 | L23: 5400 | M23: 404 | N23: 北京13组 | O23: - | P23: 1 | S23: 1 | U23: =DATEDIF(B23,"2025-6-30","y") -> 7 | W23: 已续费 | Z23: hu_jiwei@foxmail.com
A24: =ROW()-1 -> 23 | B24: 42970 | C24: 46203 | D24: 沈旸 | E24: 男 | F24: 0 | G24: 北京 | I24: 联易融 | J24: 副总裁 | K24: 标准会员 | L24: 5400 | M24: 407 | N24: 北京12组 | O24: - | P24: 1 | U24: =DATEDIF(B24,"2025-6-30","y") -> 7 | W24: 已续费 | Z24: yang.shen.it@gmail.com
A25: =ROW()-1 -> 24 | B25: 42988 | C25: 46203 | D25: 杨威 | E25: 男 | F25: １ | G25: 北京 | I25: 明略科技 | J25: 技术副总裁 | K25: 标准会员 | L25: 5400 | M25: 81 | N25: 北京0组 | O25: - | P25: 1 | U25: =DATEDIF(B25,"2025-6-30","y") -> 7 | W25: 已续费 | Z25: yangwei@rongcloud.cn
A26: =ROW()-1 -> 25 | B26: 43000 | C26: 46203 | D26: 褚亮 | E26: 男 | F26: １ | G26: 杭州 | I26: 杭州咿啦科技有限公司 | J26: 联合创始人 & CTO | K26: 标准会员 | L26: 5400 | M26: 418 | O26: - | P26: 1 | S26: 1 | U26: =DATEDIF(B26,"2025-6-30","y") -> 7 | Z26: chuliang@ellabook.cn
A27: =ROW()-1 -> 26 | B27: 43004 | C27: 46203 | D27: 沈淦 | E27: 男 | F27: １ | G27: 杭州 | I27: 杭州正马软件科技有限公司 | J27: CTO | K27: 标准会员 | L27: 5400 | M27: 419 | O27: - | P27: 1 | U27: =DATEDIF(B27,"2025-6-30","y") -> 7 | Z27: floatin@sina.com
A28: =ROW()-1 -> 27 | B28: 43006 | C28: 46203 | D28: 蒋宏飞 | E28: 男 | F28: １ | G28: 北京 | I28: 作业帮 | J28: 研究员 | K28: 标准会员 | L28: 5400 | M28: 423 | N28: 北京16组 | O28: - | P28: 1 | S28: 1 | U28: =DATEDIF(B28,"2025-6-30","y") -> 7 | W28: 已续费 | Z28: hf.jiang@qq.com
A29: =ROW()-1 -> 28 | B29: 43017 | C29: 46203 | D29: 苏锐 | E29: 男 | F29: １ | G29: 北京 | I29: Juicedata, Inc | J29: 合伙人 | K29: 标准会员 | L29: 5400 | M29: 424 | N29: 北京0组 | O29: - | P29: 1 | U29: =DATEDIF(B29,"2025-6-30","y") -> 7 | W29: 已续费 | Z29: suave.su@gmail.com
A30: =ROW()-1 -> 29 | B30: 43051 | C30: 46203 | D30: 王志刚 | E30: 男 | F30: １ | G30: 深圳 | I30: 招商基金 | J30: 副总监 | K30: 标准会员 | L30: 5400 | M30: 433 | O30: - | P30: 1 | S30: 1 | U30: =DATEDIF(B30,"2025-6-30","y") -> 7 | Z30: zhigang78@163.com
A31: =ROW()-1 -> 30 | B31: 43069 | C31: 46203 | D31: 欧文盛 | E31: 男 | F31: １ | G31: 北京 | I31: 北京泰迪熊移动科技有限公司 | J31: CTO | K31: 高级会员 | L31: 9216 | M31: 439 | N31: 北京33组 | O31: - | P31: 1 | U31: =DATEDIF(B31,"2025-6-30","y") -> 7 | W31: 已续费 | Z31: ouwensheng@teddymobile.cn
A32: =ROW()-1 -> 31 | B32: 43080 | C32: 46203 | D32: 王浩 | E32: 男 | F32: 0 | G32: 上海 | I32: 贵州小爱机器人科技有限公司 | J32: CTO | K32: 标准会员 | L32: 5400 | M32: 443 | O32: - | P32: 1 | U32: =DATEDIF(B32,"2025-6-30","y") -> 7 | Z32: wanghao@metasigncloud.com
A33: =ROW()-1 -> 32 | B33: 43082 | C33: 46203 | D33: 樊伟伟 | E33: 男 | F33: １ | G33: 南京 | I33: 微鲤 | J33: 技术总监 | K33: 标准会员 | L33: 5400 | M33: 444 | O33: - | P33: 1 | U33: =DATEDIF(B33,"2025-6-30","y") -> 7 | Z33: fanweiwei@weli.cn
A34: =ROW()-1 -> 33 | B34: 43095 | C34: 46203 | D34: 肖剑涛 | E34: 男 | F34: １ | G34: 北京 | I34: 成绎半导体 | J34: 联合创始人 | K34: 标准会员 | L34: 5400 | M34: 449 | N34: 北京22组 | O34: - | P34: 1 | U34: =DATEDIF(B34,"2025-6-30","y") -> 7 | W34: 已续费 | Z34: xiaojiantao@vip.sina.com
A35: =ROW()-1 -> 34 | B35: 43095 | C35: 46203 | D35: 李少春 | E35: 男 | F35: １ | G35: 广州 | I35: 广州博泰数据有限公司 | J35: 总经理 | K35: 标准会员 | L35: 5400 | M35: 451 | O35: - | P35: 1 | U35: =DATEDIF(B35,"2025-6-30","y") -> 7 | Z35: cylsc@163.com
A36: =ROW()-1 -> 35 | B36: 43096 | C36: 46203 | D36: 于君泽 | E36: 男 | F36: １ | G36: 成都 | I36: 中生代技术 | J36: 创始人 | K36: 标准会员 | L36: 5400 | M36: 452 | O36: - | P36: 1 | U36: =DATEDIF(B36,"2025-6-30","y") -> 7 | Z36: 5581012@qq.com
A37: =ROW()-1 -> 36 | B37: 43098 | C37: 46203 | D37: 李列为 | E37: 男 | F37: １ | G37: 南京 | I37: 江苏华博实业集团有限公司 | J37: CTO | K37: 标准会员 | L37: 5400 | M37: 453 | O37: - | P37: 1 | U37: =DATEDIF(B37,"2025-6-30","y") -> 7 | Z37: 7538350@qq.com
A38: =ROW()-1 -> 37 | B38: 43117 | C38: 46203 | D38: 邹永强 | E38: 男 | F38: 0 | G38: 北京 | I38: 云账户 | J38: 联合创始人兼CTO | K38: 高级会员 | L38: 9216 | M38: 456 | N38: 北京24组 | O38: - | P38: 1 | S38: 1 | U38: =DATEDIF(B38,"2025-6-30","y") -> 7 | W38: 已续费 | Z38: yongqiangzou@gmail.com
A39: =ROW()-1 -> 38 | B39: 43128 | C39: 46203 | D39: 马力遥 | E39: 男 | F39: １ | G39: 成都 | I39: 互联极简网络科技成都有限公司 | J39: 联合创始人 CTO | K39: 标准会员 | L39: 5400 | M39: 460 | O39: - | P39: 1 | U39: =DATEDIF(B39,"2025-6-30","y") -> 7 | Z39: nelson.ma@gsafer.com
A40: =ROW()-1 -> 39 | B40: 43132 | C40: 46203 | D40: 吴传兵 | E40: 男 | F40: １ | G40: 广州 | I40: 广州味美优品食品科技有限公司 | J40: CTO | K40: 标准会员 | L40: 5400 | M40: 462 | O40: - | P40: 1 | U40: =DATEDIF(B40,"2025-6-30","y") -> 7 | Z40: whueric@gmail.com
...

Sheet 26年续费金额
A1: 地区 | B1: 求和:续费金额 | C1: 计数:姓名
A2: 北京 | B2: 1730160 | C2: 225
A3: 杭州 | B3: 418184 | C3: 65
A4: 广州 | B4: 637056 | C4: 89
A5: 成都 | B5: 290832 | C5: 46
A6: 硅谷 | B6: 45432 | C6: 14
A7: 深圳 | B7: 888120 | C7: 115
A8: 上海 | B8: 1492776 | C8: 198
A9: 苏州 | B9: 91512 | C9: 14
A10: 南京 | B10: 196248 | C10: 34
A11: 台北 | B11: 91800 | C11: 17
A12: 武汉 | B12: 26160 | C12: 5
A13: 厦门 | B13: 95520 | C13: 18
... A15: 总计 | B15: 6005848 | C15: 841

Sheet 硅谷名单
A1: 待续费会员
A2: 加入时间 | B2: 会籍时间 | C2: 姓名 | D2: 地区 | E2: 公司 | F2: 职位 | G2: 会员类型 | H2: 续费金额
A3: 43976 | B3: 45838 | C3: 张云浩 | D3: 硅谷 | E3: 力扣（LeetCode） | F3: CEO | G3: 高级会员 | H3: 1430
A4: 44228 | B4: 45473 | C4: 王雄 | D4: 硅谷 | E4: 腾讯 | F4: 技术专家 | G4: 高级会员 | H4: 2860
A5: 44316 | B5: 45838 | C5: 曹翔 | D5: 硅谷 | E5: Tik Tok | G5: 高级会员 | H5: 1430
A6: 44565 | B6: 45838 | C6: 王泳帅 | D6: 硅谷 | E6: 宝洁 | F6: CTO | G6: 高级会员 | H6: 1430
A7: 45133 | B7: 45657 | C7: 张俊伟 | D7: 硅谷 | E7: Doordash | F7: Marketplace Tech Lead | G7: 高级会员 | H7: 2145
A8: 45159 | B8: 45838 | C8: 刘正一 James | D8: 硅谷 | E8: 阿里云 | F8: Director of New Business & Innov | G8: 高级会员 | H8: 1430
A9: 43210 | B9: 45657 | C9: 孙超 | D9: 硅谷 | E9: 西部数据 | F9: 高级技术专家 | G9: 高级会员 | H9: 2145
A10: 43210 | B10: 45657 | C10: 潘洋洋 | D10: 硅谷 | E10: VMware | F10: 高级经理 | G10: 高级会员 | H10: 2145
A11: 45262 | B11: 45657 | C11: 叶谦 | D11: 硅谷 | E11: Celerdata Inc. | F11: 联合创始人和COO | G11: 高级会员 | H11: 2145
A12: 45276 | B12: 45657 | C12: 鲁颖 | D12: 硅谷 | E12: Zoom | F12: 研发总监 | G12: 高级会员 | H12: 2145
A13: 42676 | B13: 45657 | C13: 黄东旭 | D13: 硅谷 | E13: PingCAP | F13: CTO | G13: 高级会员 | H13: 2145
A14: 45281 | B14: 45657 | C14: 杨润德 | D14: 硅谷 | E14: Dream Voyage | F14: 联合创始人 | G14: 高级会员 | H14: 2145
A15: 45289 | B15: 45657 | C15: 谢超（星爵） | D15: 硅谷 | E15: Ziliz | F15: CEO | G15: 高级会员 | H15: 2145
A16: 45289 | B16: 45657 | C16: 沙振宇 | D16: 硅谷 | E16: plus.ai | F16: senior staff engineer | G16: 高级会员 | H16: 2145
A17: 45293 | B17: 45657 | C17: 魏长帅 | D17: 硅谷 | E17: LinkedIn | F17: Sr Staff ML Engineer | G17: 高级会员 | H17: 2145
... A31: 45575 | B31: 45940 | C31: Qingsong Wen | D31: 硅谷 | E31: 松鼠AI | F31: 首席科学兼AI研究院院长 | G31: 高级会员 | H31: 2383
A33: 在籍会员
A34: 加入时间 | B34: 会籍时间 | C34: 姓名 | D34: 地区 | E34: 公司 | F34: 职位 | G34: 会员类型
A35: 42838 | B35: 46203 | C35: 任腾 | D35: 硅谷 | E35: AI Rudder | F35: CEO | G35: 标准会员
A36: 43308 | B36: 46934 | C36: 夏澎 | D36: 硅谷 | E36: 博世 | F36: 架构总监 | G36: 标准会员
A37: 44325 | B37: 46203 | C37: 杨森 | D37: 硅谷 | E37: 点线面体 | F37: CEO | G37: 标准会员
A38: 44894 | B38: 46203 | C38: 肖伦文 | D38: 硅谷 | E38: 上海吉谛科技有限公司 | F38: CEO | G38: 标准会员
A39: 45162 | B39: 46203 | C39: 刘洋 | D39: 硅谷 | E39: ScaleFlux Inc. | F39: Chief Architect | G39: 标准会员
A40: 45231 | B40: 46203 | C40: 王文锋 | D40: 硅谷 | E40: Lifecycle AI | F40: CEO | G40: 标准会员
A41: 45295 | B41: 46203 | C41: Tracy Yu | D41: 硅谷 | E41: 大众集团 | F41: 工程经理 | G41: 高级会员
A42: 45490 | B42: 46203 | C42: 董昊 | D42: 硅谷 | E42: Meta | F42: 技术经理/主管 | G42: 高级会员
A43: 45670 | B43: 46203 | C43: Yanjia Guo | D43: 硅谷 | E43: Mathos AI | F43: 联合创始人 | G43: 高级会员
A44: 45679 | B44: 46203 | C44: 段威 | D44: 硅谷 | E44: Snapchat | F44: machine learning engineer, tech lead | G44: 高级会员
A45: 45742 | B45: 46203 | C45: 杨莹 | D45: 硅谷 | E45: Niantic | F45: Product Lead, Growth | G45: 高级会员
A46: 45769 | B46: 46203 | C46: 俞舟 | D46: 硅谷 | E46: Arklex.ai | F46: 联合创始人 | G46: 高级会员
... A50: 45885 | B50: 46203 | C50: 和昊原 | D50: 硅谷 | E50: Netflix | F50: Software Engineer | G50: 高级会员

Sheet 10.31日会籍人数透视
A1: 会籍时间 | B1: (多项)
A3: 地区 | B3: 计数:姓名
A4: 总计

Sheet 新增会员推荐
A1: 2025年新会员入会分布 | F1: 年(加入时间) | G1: 计数:姓名
A2: 序号 | B2: 推荐类别 | C2: 数量 | D2: 比例 | F2: 2015年 | G2: 27
A3: 1 | B3: 自然流量 | C3: 24 | D3: =C3/191 -> 0.12565445 | F3: 2016年 | G3: 45
A4: 2 | B4: 会员推荐 | C4: 132 | D4: =C4/191 -> 0.69109948 | E4: 25年新会员推荐入会人数：6 | F4: 2017年 | G4: 48
A5: 3 | B5: infoQ | C5: 8 | D5: =C5/191 -> 0.041884817 | F5: 2018年 | G5: 94
A6: 4 | B6: 潜在会员 | C6: 3 | D6: =C6/191 -> 0.015706806 | F6: 2019年 | G6: 97
A7: 5 | B7: Kevin | C7: 6 | D7: =C7/191 -> 0.031413613 | F7: 2020年 | G7: 79
A8: 6 | B8: GTLC | C8: 8 | D8: =C8/191 -> 0.041884817 | F8: 2021年 | G8: 99
A9: 7 | B9: 公司 | C9: 2 | D9: =C9/191 -> 0.010471204 | F9: 2022年 | G9: 106
A10: 8 | B10: 老会员回归 | C10: 5 | D10: =C10/191 -> 0.02617801 | F10: 2023年 | G10: 167
A11: 9 | B11: 分会活动 | C11: 2 | D11: =C11/191 -> 0.010471204 | F11: 2024年 | G11: 190
A12: 10 | B12: Selina | C12: 1 | D12: =C12/191 -> 0.0052356021 | F12: 2025年 | G12: 224
A13: 总计 | B13: 25年新增会员 | C13: =SUM(C3:C12) -> 191 | F13: 2026年 | G13: 36
F14: 总计 | G14: 1212
A17: 加入时间 - 年份 | B17: (全部)
A18: 加入时间 - 月份 | B18: (全部)
D19: 入会时间
A20: 推荐大类 | B20: 推荐人 | C20: 计数:姓名 | D20: {=_xlfn.XLOOKUP(B20,会员总表!D:D,会员总表!B:B)} -> #N/A
A21: 暂无 | B21: 暂无 | C21: 654 | D21: {=_xlfn.XLOOKUP(B21,会员总表!D:D,会员总表!B:B)} -> #N/A
A22: 暂无 汇总 | C22: 654 | D22: {=_xlfn.XLOOKUP(B22,会员总表!D:D,会员总表!B:B)} -> 0
A23: 自然流量 | B23: 自然流量-官网 | C23: 10 | D23: {=_xlfn.XLOOKUP(B23,会员总表!D:D,会员总表!B:B)} -> #N/A | E23: 1
B24: 自然流量-朋友 | C24: 4 | D24: {=_xlfn.XLOOKUP(B24,会员总表!D:D,会员总表!B:B)} -> #N/A
B25: 自然流量-公众号 | C25: 6 | D25: {=_xlfn.XLOOKUP(B25,会员总表!D:D,会员总表!B:B)} -> #N/A
B26: 自然流量-朋友圈 | C26: 4 | D26: {=_xlfn.XLOOKUP(B26,会员总表!D:D,会员总表!B:B)} -> #N/A
B27: 乔新亮 | C27: 1 | D27: {=_xlfn.XLOOKUP(B27,会员总表!D:D,会员总表!B:B)} -> #N/A
B28: 自然流量 | C28: 9 | D28: {=_xlfn.XLOOKUP(B28,会员总表!D:D,会员总表!B:B)} -> #N/A
B29: 自然流量-知乎 | C29: 1 | D29: {=_xlfn.XLOOKUP(B29,会员总表!D:D,会员总表!B:B)} -> #N/A
B30: 自然流量-deepseek | C30: 1 | D30: {=_xlfn.XLOOKUP(B30,会员总表!D:D,会员总表!B:B)} -> #N/A
B31: 非会员行业大佬推荐 | C31: 1 | D31: {=_xlfn.XLOOKUP(B31,会员总表!D:D,会员总表!B:B)} -> #N/A
B32: 朋友 | C32: 1 | D32: {=_xlfn.XLOOKUP(B32,会员总表!D:D,会员总表!B:B)} -> #N/A
A33: 自然流量 汇总 | C33: 38 | D33: {=_xlfn.XLOOKUP(B33,会员总表!D:D,会员总表!B:B)} -> 0
A34: 会员推荐 | B34: 郭子龙 | C34: 8 | D34: {=_xlfn.XLOOKUP(B34,会员总表!D:D,会员总表!B:B)} -> 44902
B35: 于功波 | C35: 5 | D35: {=_xlfn.XLOOKUP(B35,会员总表!D:D,会员总表!B:B)} -> 45098
B36: 杨攀 | C36: 30 | D36: {=_xlfn.XLOOKUP(B36,会员总表!D:D,会员总表!B:B)} -> 42773
B37: 赵新龙 | C37: 4 | D37: {=_xlfn.XLOOKUP(B37,会员总表!D:D,会员总表!B:B)} -> 45905
B38: 嵇伟 | C38: 6 | D38: {=_xlfn.XLOOKUP(B38,会员总表!D:D,会员总表!B:B)} -> 43462
B39: 吴炳锡 | C39: 1 | D39: {=_xlfn.XLOOKUP(B39,会员总表!D:D,会员总表!B:B)} -> #N/A
B40: 谢扬 | C40: 1 | D40: {=_xlfn.XLOOKUP(B40,会员总表!D:D,会员总表!B:B)} -> #N/A
B41: 程军 | C41: 1 | D41: {=_xlfn.XLOOKUP(B41,会员总表!D:D,会员总表!B:B)} -> #N/A
B42: 暨家愉 | C42: 2 | D42: {=_xlfn.XLOOKUP(B42,会员总表!D:D,会员总表!B:B)} -> 42874
...

Sheet 各分会人数-1024
A1: 加入时间 - 年份 | B1: (全部)
A2: 加入时间 - 季度 | B2: (全部)
A3: 加入时间 - 月份 | B3: (全部)
A5: 地区 | B5: 计数:姓名
A6: 深圳 | B6: 143
A7: 杭州 | B7: 83
A8: 北京 | B8: 294
A9: 上海 | B9: 261
A10: 广州 | B10: 107
A11: 新加坡 | B11: 24
A12: 苏州 | B12: 22
A13: 南京 | B13: 44
A14: 成都 | B14: 47
A15: 硅谷 | B15: 46
A16: 武汉 | B16: 18
A17: 厦门 | B17: 25
... A19: 总计 | B19: 1131

Sheet 各分会人数-9月
A1: 加入时间 - 年份 | B1: (全部)
A2: 加入时间 - 季度 | B2: (全部)
A3: 加入时间 - 月份 | B3: (全部)
A5: 地区 | B5: 计数:姓名
A6: 深圳 | B6: 143
A7: 杭州 | B7: 83
A8: 北京 | B8: 294
A9: 上海 | B9: 261
A10: 广州 | B10: 107
A11: 新加坡 | B11: 24
A12: 苏州 | B12: 22
A13: 南京 | B13: 44
A14: 成都 | B14: 47
A15: 硅谷 | B15: 46
A16: 武汉 | B16: 18
A17: 厦门 | B17: 25
... A19: 总计 | B19: 1131

Sheet Sheet20
A1: member (4)
A2: 姓名 | B2: 手机 | C2: 公司 | D2: 职位 | E2: 邮箱 | F2: 分会 | G2: 会员类型 | H2: 加入时间 | I2: 到期时间
A3: 蔡铁 | B3: 广东九四智能科技有限公司 | C3: 13570953397 | D3: 高级技术总监 | E3: fragcai@qq.com | F3: 广州 | G3: 高级会员 | H3: 45842 | I3: 46203
A4: 张昕伟 | B4: VIPKid | C4: 15210231787 | D4: 技术总监 | E4: zhangxinwei@vipkid.com.cn | F4: 北京 | G4: 高级会员 | H4: 45846 | I4: 46203 | J4: 1
A5: 朱晓战 | B5: 全房通 | C5: 15652486096 | D5: 联合创始人 | E5: zhuxiaozhan@huizhaofang.com | F5: 北京 | G5: 高级会员 | H5: 45841 | I5: 46203 | J5: 2
A6: 朱威 | B6: 中邮消费金融有限公司 | C6: 18620668926 | D6: 其他 | E6: zhuwei@youcash.com | F6: 广州 | G6: 高级会员 | H6: 45842 | I6: 46203
A7: 邓思宇 | B7: 美高域集团HK1985 | C7: 18800356315 | D7: 技术VP/副总裁 | E7: siyudeng@microware.com.hk | F7: 深圳 | G7: 高级会员 | H7: 45826 | I7: 46203
A8: 吴永欢 | B8: 阿里云计算有限公司 | C8: 13632266659 | D8: 其他 | E8: 13632266659@qq.com | F8: 广州 | G8: 高级会员 | H8: 45846 | I8: 46203
A9: 孙翔舟 | B9: One Silver Sea | C9: 13501652230 | D9: CEO | E9: jonassun@mit.edu | F9: 深圳 | G9: 高级会员 | H9: 45833 | I9: 46203
A10: 李京林 | B10: DeerAPI | C10: 18601790523 | D10: CEO | E10: sonicli1983@163.com | F10: 上海 | G10: 高级会员 | H10: 45833 | I10: 46203
A11: 朱浩齐 | B11: 杭州网易智企科技有限公司 | C11: 13588735983 | D11: 总经理 | E11: zhuhaoqi@163.com | F11: 杭州 | G11: 高级会员 | H11: 45846 | I11: 46203
A12: 陈石 | B12: 峰瑞资本 | C12: 13801395480 | D12: 其他 | E12: bjchens@163.com | F12: 北京 | G12: 高级会员 | H12: 45826 | I12: 46203
A13: 吕琳 | B13: 英伟达 | C13: 13817054786 | D13: 其他 | E13: flowsands@qq.com | F13: 上海 | G13: 高级会员 | H13: 45832 | I13: 46203
A14: 刘泽辰 | B14: 医纪元 | C14: 13261754302 | D14: 联合创始人 | E14: liuzechen001@gmail.com | F14: 北京 | G14: 高级会员 | H14: 45840 | I14: 46203
A15: 陈志鉴 | B15: 和讯信息科技有限公司 | C15: 18518317941 | D15: 高级技术总监 | E15: chenzhijian@staff.hexun.com | F15: 北京 | G15: 高级会员 | H15: 45828 | I15: 46203
A16: 郑治东 | B16: 和讯网 | C16: 13718810082 | D16: 运维总监 | E16: zzd.ok@163.com | F16: 北京 | G16: 高级会员 | H16: 45828 | I16: 46203
A17: 周栋 | B17: 和讯信息科技有限公司 | C17: 18500388222 | D17: 技术总监 | E17: zhdong@staff.hexun.com | F17: 北京 | G17: 高级会员 | H17: 45828 | I17: 46203
... A208: 赵成业 | B208: 北京极智嘉机器人股份有限公司 | C208: 18616955651 | D208: 技术经理/主管 | E208: chengyezhao@gmail.com | F208: 上海 | G208: 高级会员 | H208: 45447 | I208: 46203
A209: 王志军 | B209: 中国联通 | C209: 18601105055 | D209: 技术VP/副总裁 | E209: wangzhijun1@chinaunicom.cn | G209: 高级会员 | H209: 45441 | I209: 45838
A210: 李红林 | B210: 东风汽车 | C210: 18602757512 | D210: 技术经理/主管 | E210: lihongl@dfmc.com.cn | G210: 高级会员 | H210: 45441 | I210: 45838
A211: 宋森 | B211: 清华大学 | C211: 18633333333 | D211: 其他 | E211: songsen@tsinghua.edu.cn | G211: 高级会员 | H211: 45441 | I211: 45838
A212: 袁粒 | B212: 北京大学深圳研究生院 | C212: 15656569683 | D212: 其他 | E212: yuanli-ece@pku.edu.cn | G212: 高级会员 | H212: 45441 | I212: 45838
A213: 吴甘沙 | B213: 驭势科技 | C213: 18610130118 | D213: CEO | E213: gansha.wu@uisee.com | G213: 高级会员 | H213: 45441 | I213: 45838
A214: 朱如江 | B214: 南通巨联数字科技有限公司 | C214: 13921628181 | D214: 技术VP/副总裁 | E214: zhurj@lianfa.cn | G214: 高级会员 | H214: 45441 | I214: 45838
A215: 刘昊 | B215: 北京泰迪未来科技 | C215: 18811180669 | D215: 技术VP/副总裁 | E215: guzi5618@qq.com | F215: 北京 | G215: 高级会员 | H215: 45457 | I215: 46203
A216: 鲍炎焱 | B216: 江苏版石软件股份有限公司 | C216: 18610527133 | D216: CTO | E216: 906425059@qq.com | F216: 北京 | G216: 高级会员 | H216: 45442 | I216: 46203
A217: 宋壬初 | B217: Epsilla | C217: 6073798668 | D217: CEO | E217: richard@epsilla.com | F217: 硅谷 | G217: 高级会员 | H217: 45447 | I217: 45812
A218: 张骏峰 | B218: 保时捷(上海)数字科技有限公司 | C218: 18601160302 | D218: CTO | E218: zhangjf@hotmail.com | F218: 北京 | G218: 高级会员 | H218: 45447 | I218: 45838
A219: 高驰涛 | B219: 云智慧（北京）科技有限公司 | C219: 13426211917 | D219: 其他 | E219: neeke.gao@hotmail.com | F219: 北京 | G219: 高级会员 | H219: 45454 | I219: 46203
A220: 高阳Sunny | B220: SegmentFault 思否 | C220: 18668162049 | D220: CEO | E220: sunny@sifou.com | F220: 杭州 | G220: 高级会员 | H220: 45446 | I220: 45838
A221: 张鹏 | B221: 知乎 | C221: 13752028021 | D221: 其他 | E221: 825817512@qq.com | F221: 北京 | G221: 高级会员 | H221: 45440 | I221: 45838
A222: 徐素文 | B222: 天度（厦门）科技股份有限公司 | C222: 18030158268 | D222: 联合创始人 | E222: wayne@tduvr.com | F222: 厦门 | G222: 高级会员 | H222: 45446 | I222: 46203
A223: 胡兵 | B223: 腾讯科技（深圳）有限公司 | C223: 18806653007 | D223: 其他 | E223: 421654305@qq.com | F223: 深圳 | G223: 高级会员 | H223: 45510 | I223: 46203
A224: 田冰 | B224: 南京百丝特网络科技有限公司 | C224: 18021519611 | D224: 其他 | E224: 501266561@qq.com | F224: 南京 | G224: 高级会员 | H224: 45450 | I224: 45838
A225: 杨金全 | B225: 北京基调网络股份有限公司 | C225: 15010968269 | D225: 技术VP/副总裁 | E225: yangjq@tingyun.com | F225: 北京 | G225: 高级会员 | H225: 45446 | I225: 46203
A226: 周卫林 | B226: 浙江大应科技有限公司 | C226: 15988160608 | D226: CEO | E226: jingzhi.zhou@aloudata.com | F226: 杭州 | G226: 高级会员 | H226: 45443 | I226: 45838
... A228: 李斌 | B228: 沐瞳科技 | C228: 13691562071 | D228: 技术VP/副总裁 | E228: 119579481@qq.com | F228: 上海 | G228: 高级会员 | H228: 45423 | I228: 45838
A229: 王曦 | B229: 杉数科技 | C229: 18610196656 | D229: 联合创始人 | E229: jack.xwang@gmail.com | G229: 高级会员 | H229: 45413 | I229: 45838
A230: 刘荣逵 | B230: 天弘基金 | C230: 18600397681 | D230: CIO | E230: rongkui.liu@gmail.com | G230: 高级会员 | H230: 45441 | I230: 45838
A231: 王浩宇 | B231: 宁波新物云科技有限公司 | C231: 13851821123 | D231: CEO | E231: damai@xinwuyun.com | G231: 高级会员 | H231: 45441 | I231: 45838
...

Sheet 各分会人数
A1: 加入时间 - 年份 | B1: (全部)
A2: 加入时间 - 季度 | B2: (全部)
A3: 加入时间 - 月份 | B3: (全部)
A5: 地区 | B5: 计数:姓名
A6: 深圳 | B6: 143
A7: 杭州 | B7: 83
A8: 北京 | B8: 294
A9: 上海 | B9: 261
A10: 广州 | B10: 107
A11: 新加坡 | B11: 24
A12: 苏州 | B12: 22
A13: 南京 | B13: 44
A14: 成都 | B14: 47
A15: 硅谷 | B15: 46
A16: 武汉 | B16: 18
A17: 厦门 | B17: 25
... A19: 总计 | B19: 1131

Sheet 数据透视表
A1: 地区 | B1: 计数:序号
A2: 上海 | B2: 246
A3: 总计 | B3: 246 | O3: 深圳3年以上 | P3: =I8 -> 0 | R3: 选这个+8个会长（不含新加坡、台北）
O4: 广州5年以上 | P4: =G9 -> 0
O5: 厦门5年以上 | P5: =G10 -> 0
O6: 合计 | P6: =SUM(P3:P5) -> 0 | Q6: =P6*400 -> 0
S7: =103+8 -> 111
A8: 深圳年份合计 | B8: =SUM(B5) -> 0 | C8: =SUM($B$5:C5) -> 0 | D8: =SUM($B$5:D5) -> 0 | E8: =SUM($B$5:E5) -> 0 | F8: =SUM($B$5:F5) -> 0 | G8: =SUM($B$5:G5) -> 0 | H8: =SUM($B$5:H5) -> 0 | I8: =SUM($B$5:I5) -> 0 | J8: =SUM($B$5:J5) -> 0 | ... L8: =SUM($B$5:L5) -> 0 | O8: 深圳2年以上 | P8: =J8 -> 0
A9: 广州年份合计 | B9: =SUM(B6) -> 0 | C9: =SUM($B$6:C6) -> 0 | D9: =SUM($B$6:D6) -> 0 | E9: =SUM($B$6:E6) -> 0 | F9: =SUM($B$6:F6) -> 0 | G9: =SUM($B$6:G6) -> 0 | H9: =SUM($B$6:H6) -> 0 | I9: =SUM($B$6:I6) -> 0 | J9: =SUM($B$6:J6) -> 0 | ... L9: =SUM($B$6:L6) -> 0 | O9: 广州5年以上 | P9: 32
A10: 厦门年份合计 | B10: =SUM(B7) -> 0 | C10: =SUM($B$7:C7) -> 0 | D10: =SUM($B$7:D7) -> 0 | E10: =SUM($B$7:E7) -> 0 | F10: =SUM($B$7:F7) -> 0 | G10: =SUM($B$7:G7) -> 0 | H10: =SUM($B$7:H7) -> 0 | I10: =SUM($B$7:I7) -> 0 | J10: =SUM($B$7:J7) -> 0 | ... L10: =SUM($B$7:L7) -> 0 | O10: 厦门5年以上 | P10: 8
O11: 合计 | P11: =SUM(P8:P10) -> 40 | Q11: =P11*400 -> 16000
O13: 深圳1年以上 | P13: =K8 -> 0
O14: 广州8年以上 | P14: =D9 -> 0
O15: 厦门8年以上 | P15: =C10 -> 0
O16: 合计 | P16: =SUM(P13:P15) -> 0 | Q16: =P16*400 -> 0
P19: =119*400 -> 47600
P20: =110*400 -> 44000
O21: =104+8 -> 112 | P21: =O21*400 -> 44800
B27: 姓名 | C27: 所在分会
B28: 洪小军 | C28: 深圳 | D28: =VLOOKUP(B28,会员总表!D:M,6,0) -> 暂无 | E28: =VLOOKUP(B28,会员总表!D:M,7,0) -> １
B29: 肖伦文 | C29: 硅谷分会 | D29: =VLOOKUP(B29,会员总表!D:M,6,0) -> 暂无 | E29: =VLOOKUP(B29,会员总表!D:M,7,0) -> 1
B30: 鲍博 | C30: 北京 | D30: =VLOOKUP(B30,会员总表!D:M,6,0) -> 会员推荐 | E30: =VLOOKUP(B30,会员总表!D:M,7,0) -> 0
B31: 夏澎 | C31: 硅谷 | D31: =VLOOKUP(B31,会员总表!D:M,6,0) -> 暂无 | E31: =VLOOKUP(B31,会员总表!D:M,7,0) -> ０
B32: 林群书 | C32: 硅谷 | D32: =VLOOKUP(B32,会员总表!D:M,6,0) -> 会员推荐 | E32: =VLOOKUP(B32,会员总表!D:M,7,0) -> 1
B33: 林旅强 | C33: 北京 | D33: =VLOOKUP(B33,会员总表!D:M,6,0) -> 会员推荐 | E33: =VLOOKUP(B33,会员总表!D:M,7,0) -> 1
B34: 姜景康 | C34: TGO杭州分会 | D34: =VLOOKUP(B34,会员总表!D:M,6,0) -> 会员推荐 | E34: =VLOOKUP(B34,会员总表!D:M,7,0) -> 0
B35: 凌馨霞 | D35: Cloudpilot AI | E35: 海外增长负责人
B36: 许小川 | C36: 深圳 | D36: =VLOOKUP(B36,会员总表!D:M,6,0) -> 会员推荐 | E36: =VLOOKUP(B36,会员总表!D:M,7,0) -> 1
B37: 张小龙 | C37: 广州 | D37: =VLOOKUP(B37,会员总表!D:M,6,0) -> 暂无 | E37: =VLOOKUP(B37,会员总表!D:M,7,0) -> 1
B38: 冯颖 | C38: 深圳 | D38: =VLOOKUP(B38,会员总表!D:M,6,0) -> 会员推荐 | E38: =VLOOKUP(B38,会员总表!D:M,7,0) -> 1
B39: 刘建国 | C39: 广州 | D39: =VLOOKUP(B39,会员总表!D:M,6,0) -> 暂无 | E39: =VLOOKUP(B39,会员总表!D:M,7,0) -> 1
B40: 王战勇 | C40: 苏州分会 | D40: =VLOOKUP(B40,会员总表!D:M,6,0) -> 会员推荐 | E40: =VLOOKUP(B40,会员总表!D:M,7,0) -> 1
B41: 逄永涛 | C41: 北京26组 | D41: =VLOOKUP(B41,会员总表!D:M,6,0) -> 暂无 | E41: =VLOOKUP(B41,会员总表!D:M,7,0) -> 1
B42: 李亚飞 | C42: 深圳 | D42: =VLOOKUP(B42,会员总表!D:M,6,0) -> 暂无 | E42: =VLOOKUP(B42,会员总表!D:M,7,0) -> 1
B43: 郭欢乐 | C43: 深圳分会 | D43: =VLOOKUP(B43,会员总表!D:M,6,0) -> 暂无 | E43: =VLOOKUP(B43,会员总表!D:M,7,0) -> 1
B44: 杜达林 | C44: 深圳分会 | D44: =VLOOKUP(B44,会员总表!D:M,6,0) -> infoQ | E44: =VLOOKUP(B44,会员总表!D:M,7,0) -> 0
B45: 王仁明 | C45: 广州会分 | D45: =VLOOKUP(B45,会员总表!D:M,6,0) -> 暂无 | E45: =VLOOKUP(B45,会员总表!D:M,7,0) -> １
B46: 杨韶伟 | C46: 广州 | D46: =VLOOKUP(B46,会员总表!D:M,6,0) -> 暂无 | E46: =VLOOKUP(B46,会员总表!D:M,7,0) -> 1
B47: 秦圆圆 | C47: 广州 | D47: =VLOOKUP(B47,会员总表!D:M,6,0) -> 会员推荐 | E47: =VLOOKUP(B47,会员总表!D:M,7,0) -> 0
... B49: 崔俊涛 | C49: 上海 | D49: =VLOOKUP(B49,会员总表!D:M,6,0) -> 暂无 | E49: =VLOOKUP(B49,会员总表!D:M,7,0) -> 0

Sheet Sheet21
A1: 姓名 | B1: 公司 | C1: 职位
A2: 郭理靖 | B2: 奈雪的茶 | C2: CTO
A3: 林华根 | B3: 安徽超远信息技术有限公司 | C3: 副总工程师
A4: 魏吉贺 | B4: 深圳市残友软件股份有限公司 | C4: 技术总监
A5: 龚银 | B5: 安克创新 | C5: CIO
A6: 高楚涛 | B6: 深圳市嘉立创科技发展有限公司 | C6: CIO
A7: 何德照 | B7: AfterShip | C7: 技术VP
A8: 张呈刚 | B8: AWS | C8: 架构师经理
A9: 冯斌 | B9: ONES | C9: CTO
A10: 宋书俊 | B10: 广州爆米科技有限公司 | C10: CTO
A11: 李晨丰 | B11: 深圳米筐科技有限公司 | C11: COO
A12: 王志刚 | B12: 招商基金 | C12: 副总监
... A111: 谢锐 | B111: 维克时光 | C111: CTO

Sheet 深圳
A1: 地区 | B1: 深圳
A3: 序号 | B3: 加入时间 | C3: 会籍时间 | D3: 姓名 | E3: 公司 | H3: 点击地区 > 点击刷新数据源 > 点击（部分）输入对应的城市
A4: 1 | B4: 42129 | C4: 46203 | D4: 艾芙（徐雁斐） | E4: 暂无
D5: 艾芙（徐雁斐） 汇总
C6: 2026/6/30 汇总
B7: 2015/5/5 汇总
A8: 1 汇总
A9: 7 | B9: 42160 | C9: 46203 | D9: 黄良懿 | E9: 高仙机器人
D10: 黄良懿 汇总
C11: 2026/6/30 汇总
B12: 2015/6/5 汇总
A13: 7 汇总
A14: 21 | B14: 42318 | C14: 46203 | D14: 林华根 | E14: 安徽超远信息技术有限公司
D15: 林华根 汇总
C16: 2026/6/30 汇总
B17: 2015/11/10 汇总
A18: 21 汇总
A19: 22 | B19: 42334 | C19: 46203 | D19: 魏吉贺 | E19: 深圳市残友软件股份有限公司
D20: 魏吉贺 汇总
C21: 2026/6/30 汇总
B22: 2015/11/26 汇总
A23: 22 汇总
A24: 23 | B24: 42339 | C24: 46203 | D24: 龚银 | E24: 安克创新
D25: 龚银 汇总
C26: 2026/6/30 汇总
B27: 2015/12/1 汇总
A28: 23 汇总
A29: 29 | B29: 42473 | C29: 46203 | D29: 高楚涛 | E29: 深圳市嘉立创科技发展有限公司
D30: 高楚涛 汇总
C31: 2026/6/30 汇总
B32: 2016/4/13 汇总
A33: 29 汇总
A34: 52 | B34: 42698 | C34: 46203 | D34: 何德照 | E34: AfterShip
D35: 何德照 汇总
C36: 2026/6/30 汇总
B37: 2016/11/24 汇总
A38: 52 汇总
A39: 53 | B39: 42706 | C39: 46203 | D39: 张呈刚 | E39: AWS
D40: 张呈刚 汇总
C41: 2026/6/30 汇总
...

Sheet 上海
A1: 地区 | B1: 上海
A3: 序号 | B3: 加入时间 | C3: 姓名 | D3: 公司 | G3: 点击地区 > 点击刷新数据源 > 点击（部分）输入对应的城市
A4: 5 | B4: 42147 | C4: 唐小浙 | D4: 墨誉科技
C5: 唐小浙 汇总
B6: 2015/5/23 汇总
A7: 5 汇总
A8: 14 | B8: 42246 | C8: 黄彬彬 | D8: 多云转晴
C9: 黄彬彬 汇总
B10: 2015/8/30 汇总
A11: 14 汇总
A12: 15 | B12: 42248 | C12: 王立博 | D12: 未来保贝
C13: 王立博 汇总
B14: 2015/9/1 汇总
A15: 15 汇总
A16: 16 | B16: 42256 | C16: 胡震 | D16: 某公链基金会
C17: 胡震 汇总
B18: 2015/9/9 汇总
A19: 16 汇总
A20: 31 | B20: 42482 | C20: 万林涛 | D20: 上海蔚星数据
C21: 万林涛 汇总
B22: 2016/4/22 汇总
A23: 31 汇总
A24: 32 | B24: 42482 | C24: 徐翎 | D24: 上海数达物流科技有限公司
C25: 徐翎 汇总
B26: 2016/4/22 汇总
A27: 32 汇总
A28: 33 | B28: 42495 | C28: 肖颖 | D28: 上海澄廓信息科技有限公司
C29: 肖颖 汇总
B30: 2016/5/5 汇总
A31: 33 汇总
A32: 34 | B32: 42524 | C32: 张剑伟 | D32: 百安居
C33: 张剑伟 汇总
B34: 2016/6/3 汇总
A35: 34 汇总
A36: 38 | B36: 42556 | C36: 陈杰 | D36: 上海领健信息技术有限公司
C37: 陈杰 汇总
B38: 2016/7/5 汇总
A39: 38 汇总
A40: 40 | B40: 42559 | C40: 黄勇 | D40: 阅流
C41: 黄勇 汇总
...

Sheet 杭州
A1: 地区 | B1: 杭州
A3: 序号 | B3: 加入时间 | C3: 会籍时间 | D3: 姓名 | E3: 公司 | H3: 点击地区 > 点击刷新数据源 > 点击（部分）输入对应的城市
A4: 2 | B4: 42132 | C4: 46203 | D4: 郭理靖 | E4: 奈雪的茶
D5: 郭理靖 汇总
C6: 2026/6/30 汇总
B7: 2015/5/8 汇总
A8: 2 汇总
A9: 36 | B9: 42537 | C9: 46203 | D9: 孙其瑞 | E9: 苏州优频科技有限公司
D10: 孙其瑞 汇总
C11: 2026/6/30 汇总
B12: 2016/6/16 汇总
A13: 36 汇总
A14: 37 | B14: 42552 | C14: 46203 | D14: 芦宇峰 | E14: 上海擎路科技
D15: 芦宇峰 汇总
C16: 2026/6/30 汇总
B17: 2016/7/1 汇总
A18: 37 汇总
A19: 58 | B19: 42731 | C19: 46203 | D19: 李卓 | E19: 道富信息科技
D20: 李卓 汇总
C21: 2026/6/30 汇总
B22: 2016/12/27 汇总
A23: 58 汇总
A24: 65 | B24: 42783 | C24: 46203 | D24: 林佳齐 | E24: 西阿爱木
D25: 林佳齐 汇总
C26: 2026/6/30 汇总
B27: 2017/2/17 汇总
A28: 65 汇总
A29: 77 | B29: 42866 | C29: 46203 | D29: 王翱宇 | E29: 杭州谐云科技有限公司
D30: 王翱宇 汇总
C31: 2026/6/30 汇总
B32: 2017/5/11 汇总
A33: 77 汇总
A34: 83 | B34: 42936 | C34: 46203 | D34: 张志成 | E34: 阿里巴巴达摩院
D35: 张志成 汇总
C36: 2026/6/30 汇总
B37: 2017/7/20 汇总
A38: 83 汇总
A39: 92 | B39: 43000 | C39: 46203 | D39: 褚亮 | E39: 杭州咿啦科技有限公司
D40: 褚亮 汇总
C41: 2026/6/30 汇总
...

Sheet 北京
A1: 地区 | B1: 北京 | H1: 点击地区 > 点击刷新数据源 > 点击（部分）输入对应的城市
A3: 序号 | B3: 加入时间 - 年份 | C3: 姓名 | D3: 公司 | H3: 点击地区 > 点击刷新数据源 > 点击（部分）输入对应的城市
A4: 3 | B4: 2015年 | C4: 陈锡言 | D4: 一览科技
C5: 陈锡言 汇总
B6: 2015年 汇总
A7: 3 汇总
A8: 4 | B8: 2015年 | C8: 汪威 | D8: 心语未来
C9: 汪威 汇总
B10: 2015年 汇总
A11: 4 汇总
A12: 8 | B12: 2015年 | C12: 史海峰 | D12: 方正证券
C13: 史海峰 汇总
B14: 2015年 汇总
A15: 8 汇总
A16: 9 | B16: 2015年 | C16: 梁宇鹏 | D16: 蓝莺IM
C17: 梁宇鹏 汇总
B18: 2015年 汇总
A19: 9 汇总
A20: 10 | B20: 2015年 | C20: 熊昌伟 | D20: 畅捷通信息技术有限公司
C21: 熊昌伟 汇总
B22: 2015年 汇总
A23: 10 汇总
A24: 12 | B24: 2015年 | C24: 陈靖华 | D24: 北京基调网络股份有限公司
C25: 陈靖华 汇总
B26: 2015年 汇总
A27: 12 汇总
A28: 13 | B28: 2015年 | C28: 侯冬雯 | D28: 北京微梦传媒
C29: 侯冬雯 汇总
B30: 2015年 汇总
A31: 13 汇总
A32: 17 | B32: 2015年 | C32: 洪强宁 | D32: 雅识科技
C33: 洪强宁 汇总
B34: 2015年 汇总
A35: 17 汇总
A36: 18 | B36: 2015年 | C36: 李道兵 | D36: Fortinet Principal Embedded Software Developer
C37: 李道兵 汇总
B38: 2015年 汇总
A39: 18 汇总
A40: 24 | B40: 2015年 | C40: 华健 | D40: 北京梦诚科技
C41: 华健 汇总
...

Sheet 广州
A1: 地区 | B1: 广州
H2: 点击地区 > 点击刷新数据源 > 点击（部分）输入对应的城市
A3: 序号 | B3: 加入时间 - 年份 | C3: 姓名 | D3: 公司
A4: 6 | B4: 2015年 | C4: 邹光先 | D4: 其他
C5: 邹光先 汇总
B6: 2015年 汇总
A7: 6 汇总
A8: 25 | B8: 2016年 | C8: 何世友 | D8: 腾讯云
C9: 何世友 汇总
B10: 2016年 汇总
A11: 25 汇总
A12: 27 | B12: 2016年 | C12: 曾冠东 | D12: 酷狗音乐
C13: 曾冠东 汇总
B14: 2016年 汇总
A15: 27 汇总
A16: 28 | B16: 2016年 | C16: 路文杰 | D16: 甘果科技
C17: 路文杰 汇总
B18: 2016年 汇总
A19: 28 汇总
A20: 30 | B20: 2016年 | C20: 刘建国 | D20: 伊智信息科技
C21: 刘建国 汇总
B22: 2016年 汇总
A23: 30 汇总
A24: 35 | B24: 2016年 | C24: 苏煦烽 | D24: 亲邻科技
C25: 苏煦烽 汇总
B26: 2016年 汇总
A27: 35 汇总
A28: 39 | B28: 2016年 | C28: 黄伟坚 | D28: mobvista汇量科技
C29: 黄伟坚 汇总
B30: 2016年 汇总
A31: 39 汇总
A32: 44 | B32: 2016年 | C32: 张志合 | D32: 广州卓越教育
C33: 张志合 汇总
B34: 2016年 汇总
A35: 44 汇总
A36: 45 | B36: 2016年 | C36: 谢金牛 | D36: 深圳风信计算机服务有限公司
C37: 谢金牛 汇总
B38: 2016年 汇总
